2020-07-06 19:08:22,607 - ERROR - Exception occurred
Traceback (most recent call last):
  File "C:\Users\Movie Computer\Desktop\certification-data-scraper\Scrapers\base_scraper.py", line 47, in run
    self.go_to_start_page()
  File "C:\Users\Movie Computer\Desktop\certification-data-scraper\Scrapers\Europe\TED_class.py", line 35, in go_to_start_page
    search_box = self.driver.find_element_by_xpath(
  File "C:\Users\Movie Computer\AppData\Local\Programs\Python\Python38\lib\site-packages\selenium\webdriver\remote\webdriver.py", line 394, in find_element_by_xpath
    return self.find_element(by=By.XPATH, value=xpath)
  File "C:\Users\Movie Computer\AppData\Local\Programs\Python\Python38\lib\site-packages\selenium\webdriver\remote\webdriver.py", line 976, in find_element
    return self.execute(Command.FIND_ELEMENT, {
  File "C:\Users\Movie Computer\AppData\Local\Programs\Python\Python38\lib\site-packages\selenium\webdriver\remote\webdriver.py", line 321, in execute
    self.error_handler.check_response(response)
  File "C:\Users\Movie Computer\AppData\Local\Programs\Python\Python38\lib\site-packages\selenium\webdriver\remote\errorhandler.py", line 242, in check_response
    raise exception_class(message, screen, stacktrace)
selenium.common.exceptions.NoSuchElementException: Message: no such element: Unable to locate element: {"method":"xpath","selector":"//*[@title="Go to the expert search form"]"}
  (Session info: chrome=83.0.4103.116)

2020-07-06 19:10:42,174 - ERROR - Exception occurred
Traceback (most recent call last):
  File "C:\Users\Movie Computer\Desktop\certification-data-scraper\Scrapers\base_scraper.py", line 64, in run
    read_write.save_pickle(self.data_list, "{}.pickle".format(self.project))
  File "C:\Users\Movie Computer\Desktop\certification-data-scraper\ScrapingTools\read_write.py", line 26, in save_pickle
    pickle_file = open(file_name, 'wb')
PermissionError: [Errno 13] Permission denied: 'TED.pickle'
2020-07-06 19:10:42,174 - WARNING - Retry no. 1
2020-07-06 19:14:15,610 - WARNING - file_cache is unavailable when using oauth2client >= 4.0.0 or google-auth
Traceback (most recent call last):
  File "C:\Users\Movie Computer\AppData\Local\Programs\Python\Python38\lib\site-packages\googleapiclient\discovery_cache\__init__.py", line 36, in autodetect
    from google.appengine.api import memcache
ModuleNotFoundError: No module named 'google.appengine'

During handling of the above exception, another exception occurred:

Traceback (most recent call last):
  File "C:\Users\Movie Computer\AppData\Local\Programs\Python\Python38\lib\site-packages\googleapiclient\discovery_cache\file_cache.py", line 33, in <module>
    from oauth2client.contrib.locked_file import LockedFile
ModuleNotFoundError: No module named 'oauth2client.contrib.locked_file'

During handling of the above exception, another exception occurred:

Traceback (most recent call last):
  File "C:\Users\Movie Computer\AppData\Local\Programs\Python\Python38\lib\site-packages\googleapiclient\discovery_cache\file_cache.py", line 37, in <module>
    from oauth2client.locked_file import LockedFile
ModuleNotFoundError: No module named 'oauth2client.locked_file'

During handling of the above exception, another exception occurred:

Traceback (most recent call last):
  File "C:\Users\Movie Computer\AppData\Local\Programs\Python\Python38\lib\site-packages\googleapiclient\discovery_cache\__init__.py", line 42, in autodetect
    from . import file_cache
  File "C:\Users\Movie Computer\AppData\Local\Programs\Python\Python38\lib\site-packages\googleapiclient\discovery_cache\file_cache.py", line 40, in <module>
    raise ImportError(
ImportError: file_cache is unavailable when using oauth2client >= 4.0.0 or google-auth
2020-07-06 19:14:20,110 - WARNING - file_cache is unavailable when using oauth2client >= 4.0.0 or google-auth
Traceback (most recent call last):
  File "C:\Users\Movie Computer\AppData\Local\Programs\Python\Python38\lib\site-packages\googleapiclient\discovery_cache\__init__.py", line 36, in autodetect
    from google.appengine.api import memcache
ModuleNotFoundError: No module named 'google.appengine'

During handling of the above exception, another exception occurred:

Traceback (most recent call last):
  File "C:\Users\Movie Computer\AppData\Local\Programs\Python\Python38\lib\site-packages\googleapiclient\discovery_cache\file_cache.py", line 33, in <module>
    from oauth2client.contrib.locked_file import LockedFile
ModuleNotFoundError: No module named 'oauth2client.contrib.locked_file'

During handling of the above exception, another exception occurred:

Traceback (most recent call last):
  File "C:\Users\Movie Computer\AppData\Local\Programs\Python\Python38\lib\site-packages\googleapiclient\discovery_cache\file_cache.py", line 37, in <module>
    from oauth2client.locked_file import LockedFile
ModuleNotFoundError: No module named 'oauth2client.locked_file'

During handling of the above exception, another exception occurred:

Traceback (most recent call last):
  File "C:\Users\Movie Computer\AppData\Local\Programs\Python\Python38\lib\site-packages\googleapiclient\discovery_cache\__init__.py", line 42, in autodetect
    from . import file_cache
  File "C:\Users\Movie Computer\AppData\Local\Programs\Python\Python38\lib\site-packages\googleapiclient\discovery_cache\file_cache.py", line 40, in <module>
    raise ImportError(
ImportError: file_cache is unavailable when using oauth2client >= 4.0.0 or google-auth
2020-07-06 19:14:24,001 - WARNING - file_cache is unavailable when using oauth2client >= 4.0.0 or google-auth
Traceback (most recent call last):
  File "C:\Users\Movie Computer\AppData\Local\Programs\Python\Python38\lib\site-packages\googleapiclient\discovery_cache\__init__.py", line 36, in autodetect
    from google.appengine.api import memcache
ModuleNotFoundError: No module named 'google.appengine'

During handling of the above exception, another exception occurred:

Traceback (most recent call last):
  File "C:\Users\Movie Computer\AppData\Local\Programs\Python\Python38\lib\site-packages\googleapiclient\discovery_cache\file_cache.py", line 33, in <module>
    from oauth2client.contrib.locked_file import LockedFile
ModuleNotFoundError: No module named 'oauth2client.contrib.locked_file'

During handling of the above exception, another exception occurred:

Traceback (most recent call last):
  File "C:\Users\Movie Computer\AppData\Local\Programs\Python\Python38\lib\site-packages\googleapiclient\discovery_cache\file_cache.py", line 37, in <module>
    from oauth2client.locked_file import LockedFile
ModuleNotFoundError: No module named 'oauth2client.locked_file'

During handling of the above exception, another exception occurred:

Traceback (most recent call last):
  File "C:\Users\Movie Computer\AppData\Local\Programs\Python\Python38\lib\site-packages\googleapiclient\discovery_cache\__init__.py", line 42, in autodetect
    from . import file_cache
  File "C:\Users\Movie Computer\AppData\Local\Programs\Python\Python38\lib\site-packages\googleapiclient\discovery_cache\file_cache.py", line 40, in <module>
    raise ImportError(
ImportError: file_cache is unavailable when using oauth2client >= 4.0.0 or google-auth
2020-07-06 19:14:28,201 - WARNING - file_cache is unavailable when using oauth2client >= 4.0.0 or google-auth
Traceback (most recent call last):
  File "C:\Users\Movie Computer\AppData\Local\Programs\Python\Python38\lib\site-packages\googleapiclient\discovery_cache\__init__.py", line 36, in autodetect
    from google.appengine.api import memcache
ModuleNotFoundError: No module named 'google.appengine'

During handling of the above exception, another exception occurred:

Traceback (most recent call last):
  File "C:\Users\Movie Computer\AppData\Local\Programs\Python\Python38\lib\site-packages\googleapiclient\discovery_cache\file_cache.py", line 33, in <module>
    from oauth2client.contrib.locked_file import LockedFile
ModuleNotFoundError: No module named 'oauth2client.contrib.locked_file'

During handling of the above exception, another exception occurred:

Traceback (most recent call last):
  File "C:\Users\Movie Computer\AppData\Local\Programs\Python\Python38\lib\site-packages\googleapiclient\discovery_cache\file_cache.py", line 37, in <module>
    from oauth2client.locked_file import LockedFile
ModuleNotFoundError: No module named 'oauth2client.locked_file'

During handling of the above exception, another exception occurred:

Traceback (most recent call last):
  File "C:\Users\Movie Computer\AppData\Local\Programs\Python\Python38\lib\site-packages\googleapiclient\discovery_cache\__init__.py", line 42, in autodetect
    from . import file_cache
  File "C:\Users\Movie Computer\AppData\Local\Programs\Python\Python38\lib\site-packages\googleapiclient\discovery_cache\file_cache.py", line 40, in <module>
    raise ImportError(
ImportError: file_cache is unavailable when using oauth2client >= 4.0.0 or google-auth
