2020-07-02 16:33:22,959 - ERROR - Exception occurred
Traceback (most recent call last):
  File "C:\Users\Movie Computer\Desktop\certification-data-scraper\Scrapers\base_scraper.py", line 65, in run
    self.pagination()
  File "C:\Users\Movie Computer\Desktop\certification-data-scraper\Scrapers\Asia\eprocure.py", line 44, in pagination
    self.driver.get(self.new_link)
  File "C:\Users\Movie Computer\AppData\Local\Programs\Python\Python38\lib\site-packages\selenium\webdriver\remote\webdriver.py", line 333, in get
    self.execute(Command.GET, {'url': url})
  File "C:\Users\Movie Computer\AppData\Local\Programs\Python\Python38\lib\site-packages\selenium\webdriver\remote\webdriver.py", line 321, in execute
    self.error_handler.check_response(response)
  File "C:\Users\Movie Computer\AppData\Local\Programs\Python\Python38\lib\site-packages\selenium\webdriver\remote\errorhandler.py", line 242, in check_response
    raise exception_class(message, screen, stacktrace)
selenium.common.exceptions.NoSuchWindowException: Message: no such window: target window already closed
from unknown error: web view not found
  (Session info: chrome=83.0.4103.116)

2020-07-02 16:33:22,979 - WARNING - Retry no. 1
2020-07-02 16:33:23,004 - ERROR - Exception occurred
Traceback (most recent call last):
  File "C:\Users\Movie Computer\Desktop\certification-data-scraper\Scrapers\base_scraper.py", line 39, in run
    self.driver.get(self.link)
  File "C:\Users\Movie Computer\AppData\Local\Programs\Python\Python38\lib\site-packages\selenium\webdriver\remote\webdriver.py", line 333, in get
    self.execute(Command.GET, {'url': url})
  File "C:\Users\Movie Computer\AppData\Local\Programs\Python\Python38\lib\site-packages\selenium\webdriver\remote\webdriver.py", line 321, in execute
    self.error_handler.check_response(response)
  File "C:\Users\Movie Computer\AppData\Local\Programs\Python\Python38\lib\site-packages\selenium\webdriver\remote\errorhandler.py", line 242, in check_response
    raise exception_class(message, screen, stacktrace)
selenium.common.exceptions.NoSuchWindowException: Message: no such window: target window already closed
from unknown error: web view not found
  (Session info: chrome=83.0.4103.116)

2020-07-02 16:33:23,013 - WARNING - Retry no. 2
2020-07-02 16:33:23,054 - ERROR - Exception occurred
Traceback (most recent call last):
  File "C:\Users\Movie Computer\Desktop\certification-data-scraper\Scrapers\base_scraper.py", line 39, in run
    self.driver.get(self.link)
  File "C:\Users\Movie Computer\AppData\Local\Programs\Python\Python38\lib\site-packages\selenium\webdriver\remote\webdriver.py", line 333, in get
    self.execute(Command.GET, {'url': url})
  File "C:\Users\Movie Computer\AppData\Local\Programs\Python\Python38\lib\site-packages\selenium\webdriver\remote\webdriver.py", line 321, in execute
    self.error_handler.check_response(response)
  File "C:\Users\Movie Computer\AppData\Local\Programs\Python\Python38\lib\site-packages\selenium\webdriver\remote\errorhandler.py", line 242, in check_response
    raise exception_class(message, screen, stacktrace)
selenium.common.exceptions.NoSuchWindowException: Message: no such window: target window already closed
from unknown error: web view not found
  (Session info: chrome=83.0.4103.116)

2020-07-02 16:33:23,054 - WARNING - Retry no. 3
2020-07-02 16:33:23,054 - ERROR - Exception occurred
Traceback (most recent call last):
  File "C:\Users\Movie Computer\Desktop\certification-data-scraper\Scrapers\base_scraper.py", line 39, in run
    self.driver.get(self.link)
  File "C:\Users\Movie Computer\AppData\Local\Programs\Python\Python38\lib\site-packages\selenium\webdriver\remote\webdriver.py", line 333, in get
    self.execute(Command.GET, {'url': url})
  File "C:\Users\Movie Computer\AppData\Local\Programs\Python\Python38\lib\site-packages\selenium\webdriver\remote\webdriver.py", line 321, in execute
    self.error_handler.check_response(response)
  File "C:\Users\Movie Computer\AppData\Local\Programs\Python\Python38\lib\site-packages\selenium\webdriver\remote\errorhandler.py", line 242, in check_response
    raise exception_class(message, screen, stacktrace)
selenium.common.exceptions.NoSuchWindowException: Message: no such window: target window already closed
from unknown error: web view not found
  (Session info: chrome=83.0.4103.116)

2020-07-02 16:33:23,070 - WARNING - Retry no. 4
2020-07-02 16:33:23,086 - ERROR - Exception occurred
Traceback (most recent call last):
  File "C:\Users\Movie Computer\Desktop\certification-data-scraper\Scrapers\base_scraper.py", line 39, in run
    self.driver.get(self.link)
  File "C:\Users\Movie Computer\AppData\Local\Programs\Python\Python38\lib\site-packages\selenium\webdriver\remote\webdriver.py", line 333, in get
    self.execute(Command.GET, {'url': url})
  File "C:\Users\Movie Computer\AppData\Local\Programs\Python\Python38\lib\site-packages\selenium\webdriver\remote\webdriver.py", line 321, in execute
    self.error_handler.check_response(response)
  File "C:\Users\Movie Computer\AppData\Local\Programs\Python\Python38\lib\site-packages\selenium\webdriver\remote\errorhandler.py", line 242, in check_response
    raise exception_class(message, screen, stacktrace)
selenium.common.exceptions.NoSuchWindowException: Message: no such window: target window already closed
from unknown error: web view not found
  (Session info: chrome=83.0.4103.116)

2020-07-02 16:33:23,106 - WARNING - Retry no. 5
2020-07-02 16:33:23,106 - WARNING - Maximum retries exceeded, quitting program and saving logs.
2020-07-02 16:36:52,628 - ERROR - Exception occurred
Traceback (most recent call last):
  File "C:\Users\Movie Computer\Desktop\certification-data-scraper\Scrapers\base_scraper.py", line 64, in run
    self.pagination()
  File "C:\Users\Movie Computer\Desktop\certification-data-scraper\Scrapers\Asia\eprocure.py", line 42, in pagination
    self.driver.get(self.new_link)
  File "C:\Users\Movie Computer\AppData\Local\Programs\Python\Python38\lib\site-packages\selenium\webdriver\remote\webdriver.py", line 333, in get
    self.execute(Command.GET, {'url': url})
  File "C:\Users\Movie Computer\AppData\Local\Programs\Python\Python38\lib\site-packages\selenium\webdriver\remote\webdriver.py", line 321, in execute
    self.error_handler.check_response(response)
  File "C:\Users\Movie Computer\AppData\Local\Programs\Python\Python38\lib\site-packages\selenium\webdriver\remote\errorhandler.py", line 242, in check_response
    raise exception_class(message, screen, stacktrace)
selenium.common.exceptions.NoSuchWindowException: Message: no such window: target window already closed
from unknown error: web view not found
  (Session info: chrome=83.0.4103.116)

2020-07-02 16:36:52,651 - WARNING - Retry no. 1
2020-07-02 16:36:52,684 - ERROR - Exception occurred
Traceback (most recent call last):
  File "C:\Users\Movie Computer\Desktop\certification-data-scraper\Scrapers\base_scraper.py", line 39, in run
    self.driver.get(self.link)
  File "C:\Users\Movie Computer\AppData\Local\Programs\Python\Python38\lib\site-packages\selenium\webdriver\remote\webdriver.py", line 333, in get
    self.execute(Command.GET, {'url': url})
  File "C:\Users\Movie Computer\AppData\Local\Programs\Python\Python38\lib\site-packages\selenium\webdriver\remote\webdriver.py", line 321, in execute
    self.error_handler.check_response(response)
  File "C:\Users\Movie Computer\AppData\Local\Programs\Python\Python38\lib\site-packages\selenium\webdriver\remote\errorhandler.py", line 242, in check_response
    raise exception_class(message, screen, stacktrace)
selenium.common.exceptions.NoSuchWindowException: Message: no such window: target window already closed
from unknown error: web view not found
  (Session info: chrome=83.0.4103.116)

2020-07-02 16:36:52,689 - WARNING - Retry no. 2
2020-07-02 16:36:52,709 - ERROR - Exception occurred
Traceback (most recent call last):
  File "C:\Users\Movie Computer\Desktop\certification-data-scraper\Scrapers\base_scraper.py", line 39, in run
    self.driver.get(self.link)
  File "C:\Users\Movie Computer\AppData\Local\Programs\Python\Python38\lib\site-packages\selenium\webdriver\remote\webdriver.py", line 333, in get
    self.execute(Command.GET, {'url': url})
  File "C:\Users\Movie Computer\AppData\Local\Programs\Python\Python38\lib\site-packages\selenium\webdriver\remote\webdriver.py", line 321, in execute
    self.error_handler.check_response(response)
  File "C:\Users\Movie Computer\AppData\Local\Programs\Python\Python38\lib\site-packages\selenium\webdriver\remote\errorhandler.py", line 242, in check_response
    raise exception_class(message, screen, stacktrace)
selenium.common.exceptions.NoSuchWindowException: Message: no such window: target window already closed
from unknown error: web view not found
  (Session info: chrome=83.0.4103.116)

2020-07-02 16:36:52,716 - WARNING - Retry no. 3
2020-07-02 16:36:52,747 - ERROR - Exception occurred
Traceback (most recent call last):
  File "C:\Users\Movie Computer\Desktop\certification-data-scraper\Scrapers\base_scraper.py", line 39, in run
    self.driver.get(self.link)
  File "C:\Users\Movie Computer\AppData\Local\Programs\Python\Python38\lib\site-packages\selenium\webdriver\remote\webdriver.py", line 333, in get
    self.execute(Command.GET, {'url': url})
  File "C:\Users\Movie Computer\AppData\Local\Programs\Python\Python38\lib\site-packages\selenium\webdriver\remote\webdriver.py", line 321, in execute
    self.error_handler.check_response(response)
  File "C:\Users\Movie Computer\AppData\Local\Programs\Python\Python38\lib\site-packages\selenium\webdriver\remote\errorhandler.py", line 242, in check_response
    raise exception_class(message, screen, stacktrace)
selenium.common.exceptions.NoSuchWindowException: Message: no such window: target window already closed
from unknown error: web view not found
  (Session info: chrome=83.0.4103.116)

2020-07-02 16:36:52,752 - WARNING - Retry no. 4
2020-07-02 16:36:52,770 - ERROR - Exception occurred
Traceback (most recent call last):
  File "C:\Users\Movie Computer\Desktop\certification-data-scraper\Scrapers\base_scraper.py", line 39, in run
    self.driver.get(self.link)
  File "C:\Users\Movie Computer\AppData\Local\Programs\Python\Python38\lib\site-packages\selenium\webdriver\remote\webdriver.py", line 333, in get
    self.execute(Command.GET, {'url': url})
  File "C:\Users\Movie Computer\AppData\Local\Programs\Python\Python38\lib\site-packages\selenium\webdriver\remote\webdriver.py", line 321, in execute
    self.error_handler.check_response(response)
  File "C:\Users\Movie Computer\AppData\Local\Programs\Python\Python38\lib\site-packages\selenium\webdriver\remote\errorhandler.py", line 242, in check_response
    raise exception_class(message, screen, stacktrace)
selenium.common.exceptions.NoSuchWindowException: Message: no such window: target window already closed
from unknown error: web view not found
  (Session info: chrome=83.0.4103.116)

2020-07-02 16:36:52,775 - WARNING - Retry no. 5
2020-07-02 16:36:52,776 - WARNING - Maximum retries exceeded, quitting program and saving logs.
2020-07-02 16:42:43,901 - WARNING - file_cache is unavailable when using oauth2client >= 4.0.0 or google-auth
Traceback (most recent call last):
  File "C:\Users\Movie Computer\AppData\Local\Programs\Python\Python38\lib\site-packages\googleapiclient\discovery_cache\__init__.py", line 36, in autodetect
    from google.appengine.api import memcache
ModuleNotFoundError: No module named 'google.appengine'

During handling of the above exception, another exception occurred:

Traceback (most recent call last):
  File "C:\Users\Movie Computer\AppData\Local\Programs\Python\Python38\lib\site-packages\googleapiclient\discovery_cache\file_cache.py", line 33, in <module>
    from oauth2client.contrib.locked_file import LockedFile
ModuleNotFoundError: No module named 'oauth2client.contrib.locked_file'

During handling of the above exception, another exception occurred:

Traceback (most recent call last):
  File "C:\Users\Movie Computer\AppData\Local\Programs\Python\Python38\lib\site-packages\googleapiclient\discovery_cache\file_cache.py", line 37, in <module>
    from oauth2client.locked_file import LockedFile
ModuleNotFoundError: No module named 'oauth2client.locked_file'

During handling of the above exception, another exception occurred:

Traceback (most recent call last):
  File "C:\Users\Movie Computer\AppData\Local\Programs\Python\Python38\lib\site-packages\googleapiclient\discovery_cache\__init__.py", line 42, in autodetect
    from . import file_cache
  File "C:\Users\Movie Computer\AppData\Local\Programs\Python\Python38\lib\site-packages\googleapiclient\discovery_cache\file_cache.py", line 40, in <module>
    raise ImportError(
ImportError: file_cache is unavailable when using oauth2client >= 4.0.0 or google-auth
2020-07-02 16:46:26,716 - WARNING - file_cache is unavailable when using oauth2client >= 4.0.0 or google-auth
Traceback (most recent call last):
  File "C:\Users\Movie Computer\AppData\Local\Programs\Python\Python38\lib\site-packages\googleapiclient\discovery_cache\__init__.py", line 36, in autodetect
    from google.appengine.api import memcache
ModuleNotFoundError: No module named 'google.appengine'

During handling of the above exception, another exception occurred:

Traceback (most recent call last):
  File "C:\Users\Movie Computer\AppData\Local\Programs\Python\Python38\lib\site-packages\googleapiclient\discovery_cache\file_cache.py", line 33, in <module>
    from oauth2client.contrib.locked_file import LockedFile
ModuleNotFoundError: No module named 'oauth2client.contrib.locked_file'

During handling of the above exception, another exception occurred:

Traceback (most recent call last):
  File "C:\Users\Movie Computer\AppData\Local\Programs\Python\Python38\lib\site-packages\googleapiclient\discovery_cache\file_cache.py", line 37, in <module>
    from oauth2client.locked_file import LockedFile
ModuleNotFoundError: No module named 'oauth2client.locked_file'

During handling of the above exception, another exception occurred:

Traceback (most recent call last):
  File "C:\Users\Movie Computer\AppData\Local\Programs\Python\Python38\lib\site-packages\googleapiclient\discovery_cache\__init__.py", line 42, in autodetect
    from . import file_cache
  File "C:\Users\Movie Computer\AppData\Local\Programs\Python\Python38\lib\site-packages\googleapiclient\discovery_cache\file_cache.py", line 40, in <module>
    raise ImportError(
ImportError: file_cache is unavailable when using oauth2client >= 4.0.0 or google-auth
2020-07-02 16:50:03,275 - WARNING - file_cache is unavailable when using oauth2client >= 4.0.0 or google-auth
Traceback (most recent call last):
  File "C:\Users\Movie Computer\AppData\Local\Programs\Python\Python38\lib\site-packages\googleapiclient\discovery_cache\__init__.py", line 36, in autodetect
    from google.appengine.api import memcache
ModuleNotFoundError: No module named 'google.appengine'

During handling of the above exception, another exception occurred:

Traceback (most recent call last):
  File "C:\Users\Movie Computer\AppData\Local\Programs\Python\Python38\lib\site-packages\googleapiclient\discovery_cache\file_cache.py", line 33, in <module>
    from oauth2client.contrib.locked_file import LockedFile
ModuleNotFoundError: No module named 'oauth2client.contrib.locked_file'

During handling of the above exception, another exception occurred:

Traceback (most recent call last):
  File "C:\Users\Movie Computer\AppData\Local\Programs\Python\Python38\lib\site-packages\googleapiclient\discovery_cache\file_cache.py", line 37, in <module>
    from oauth2client.locked_file import LockedFile
ModuleNotFoundError: No module named 'oauth2client.locked_file'

During handling of the above exception, another exception occurred:

Traceback (most recent call last):
  File "C:\Users\Movie Computer\AppData\Local\Programs\Python\Python38\lib\site-packages\googleapiclient\discovery_cache\__init__.py", line 42, in autodetect
    from . import file_cache
  File "C:\Users\Movie Computer\AppData\Local\Programs\Python\Python38\lib\site-packages\googleapiclient\discovery_cache\file_cache.py", line 40, in <module>
    raise ImportError(
ImportError: file_cache is unavailable when using oauth2client >= 4.0.0 or google-auth
2020-07-02 16:51:08,343 - ERROR - Exception occurred
Traceback (most recent call last):
  File "C:\Users\Movie Computer\Desktop\certification-data-scraper\Scrapers\base_scraper.py", line 54, in run
    self.data_list.append(self.click_links())
  File "C:\Users\Movie Computer\Desktop\certification-data-scraper\Scrapers\Asia\eprocure.py", line 33, in click_links
    data = self.get_data()
  File "C:\Users\Movie Computer\Desktop\certification-data-scraper\Scrapers\Asia\eprocure.py", line 48, in get_data
    info_list.append(soup.find('td', string="ePublished Date").find_next_siblings(width="20%")[0].text.strip())
AttributeError: 'NoneType' object has no attribute 'find_next_siblings'
2020-07-02 16:51:08,352 - WARNING - Retry no. 1
2020-07-02 16:51:38,098 - ERROR - Exception occurred
Traceback (most recent call last):
  File "C:\Users\Movie Computer\Desktop\certification-data-scraper\Scrapers\base_scraper.py", line 54, in run
    self.data_list.append(self.click_links())
  File "C:\Users\Movie Computer\Desktop\certification-data-scraper\Scrapers\Asia\eprocure.py", line 33, in click_links
    data = self.get_data()
  File "C:\Users\Movie Computer\Desktop\certification-data-scraper\Scrapers\Asia\eprocure.py", line 48, in get_data
    info_list.append(soup.find('td', string="ePublished Date").find_next_siblings(width="20%")[0].text.strip())
AttributeError: 'NoneType' object has no attribute 'find_next_siblings'
2020-07-02 16:51:38,104 - WARNING - Retry no. 2
2020-07-02 17:00:18,367 - WARNING - file_cache is unavailable when using oauth2client >= 4.0.0 or google-auth
Traceback (most recent call last):
  File "C:\Users\Movie Computer\AppData\Local\Programs\Python\Python38\lib\site-packages\googleapiclient\discovery_cache\__init__.py", line 36, in autodetect
    from google.appengine.api import memcache
ModuleNotFoundError: No module named 'google.appengine'

During handling of the above exception, another exception occurred:

Traceback (most recent call last):
  File "C:\Users\Movie Computer\AppData\Local\Programs\Python\Python38\lib\site-packages\googleapiclient\discovery_cache\file_cache.py", line 33, in <module>
    from oauth2client.contrib.locked_file import LockedFile
ModuleNotFoundError: No module named 'oauth2client.contrib.locked_file'

During handling of the above exception, another exception occurred:

Traceback (most recent call last):
  File "C:\Users\Movie Computer\AppData\Local\Programs\Python\Python38\lib\site-packages\googleapiclient\discovery_cache\file_cache.py", line 37, in <module>
    from oauth2client.locked_file import LockedFile
ModuleNotFoundError: No module named 'oauth2client.locked_file'

During handling of the above exception, another exception occurred:

Traceback (most recent call last):
  File "C:\Users\Movie Computer\AppData\Local\Programs\Python\Python38\lib\site-packages\googleapiclient\discovery_cache\__init__.py", line 42, in autodetect
    from . import file_cache
  File "C:\Users\Movie Computer\AppData\Local\Programs\Python\Python38\lib\site-packages\googleapiclient\discovery_cache\file_cache.py", line 40, in <module>
    raise ImportError(
ImportError: file_cache is unavailable when using oauth2client >= 4.0.0 or google-auth
2020-07-02 17:04:02,827 - WARNING - file_cache is unavailable when using oauth2client >= 4.0.0 or google-auth
Traceback (most recent call last):
  File "C:\Users\Movie Computer\AppData\Local\Programs\Python\Python38\lib\site-packages\googleapiclient\discovery_cache\__init__.py", line 36, in autodetect
    from google.appengine.api import memcache
ModuleNotFoundError: No module named 'google.appengine'

During handling of the above exception, another exception occurred:

Traceback (most recent call last):
  File "C:\Users\Movie Computer\AppData\Local\Programs\Python\Python38\lib\site-packages\googleapiclient\discovery_cache\file_cache.py", line 33, in <module>
    from oauth2client.contrib.locked_file import LockedFile
ModuleNotFoundError: No module named 'oauth2client.contrib.locked_file'

During handling of the above exception, another exception occurred:

Traceback (most recent call last):
  File "C:\Users\Movie Computer\AppData\Local\Programs\Python\Python38\lib\site-packages\googleapiclient\discovery_cache\file_cache.py", line 37, in <module>
    from oauth2client.locked_file import LockedFile
ModuleNotFoundError: No module named 'oauth2client.locked_file'

During handling of the above exception, another exception occurred:

Traceback (most recent call last):
  File "C:\Users\Movie Computer\AppData\Local\Programs\Python\Python38\lib\site-packages\googleapiclient\discovery_cache\__init__.py", line 42, in autodetect
    from . import file_cache
  File "C:\Users\Movie Computer\AppData\Local\Programs\Python\Python38\lib\site-packages\googleapiclient\discovery_cache\file_cache.py", line 40, in <module>
    raise ImportError(
ImportError: file_cache is unavailable when using oauth2client >= 4.0.0 or google-auth
2020-07-02 17:10:55,766 - ERROR - Exception occurred
Traceback (most recent call last):
  File "C:\Users\Movie Computer\Desktop\certification-data-scraper\Scrapers\base_scraper.py", line 54, in run
    self.data_list.append(self.click_links())
  File "C:\Users\Movie Computer\Desktop\certification-data-scraper\Scrapers\Asia\eprocure.py", line 33, in click_links
    data = self.get_data()
  File "C:\Users\Movie Computer\Desktop\certification-data-scraper\Scrapers\Asia\eprocure.py", line 47, in get_data
    info_list.append(soup.find('td', string="ePublished Date").find_next_siblings(width="20%")[0].text.strip())
AttributeError: 'NoneType' object has no attribute 'find_next_siblings'
2020-07-02 17:10:55,776 - WARNING - Retry no. 1
2020-07-02 17:12:13,100 - ERROR - Exception occurred
Traceback (most recent call last):
  File "C:\Users\Movie Computer\Desktop\certification-data-scraper\Scrapers\base_scraper.py", line 54, in run
    self.data_list.append(self.click_links())
  File "C:\Users\Movie Computer\Desktop\certification-data-scraper\Scrapers\Asia\eprocure.py", line 33, in click_links
    data = self.get_data()
  File "C:\Users\Movie Computer\Desktop\certification-data-scraper\Scrapers\Asia\eprocure.py", line 47, in get_data
    info_list.append(soup.find('td', string="ePublished Date").find_next_siblings(width="20%")[0].text.strip())
AttributeError: 'NoneType' object has no attribute 'find_next_siblings'
2020-07-02 17:12:13,113 - WARNING - Retry no. 1
2020-07-02 17:13:54,056 - WARNING - file_cache is unavailable when using oauth2client >= 4.0.0 or google-auth
Traceback (most recent call last):
  File "C:\Users\Movie Computer\AppData\Local\Programs\Python\Python38\lib\site-packages\googleapiclient\discovery_cache\__init__.py", line 36, in autodetect
    from google.appengine.api import memcache
ModuleNotFoundError: No module named 'google.appengine'

During handling of the above exception, another exception occurred:

Traceback (most recent call last):
  File "C:\Users\Movie Computer\AppData\Local\Programs\Python\Python38\lib\site-packages\googleapiclient\discovery_cache\file_cache.py", line 33, in <module>
    from oauth2client.contrib.locked_file import LockedFile
ModuleNotFoundError: No module named 'oauth2client.contrib.locked_file'

During handling of the above exception, another exception occurred:

Traceback (most recent call last):
  File "C:\Users\Movie Computer\AppData\Local\Programs\Python\Python38\lib\site-packages\googleapiclient\discovery_cache\file_cache.py", line 37, in <module>
    from oauth2client.locked_file import LockedFile
ModuleNotFoundError: No module named 'oauth2client.locked_file'

During handling of the above exception, another exception occurred:

Traceback (most recent call last):
  File "C:\Users\Movie Computer\AppData\Local\Programs\Python\Python38\lib\site-packages\googleapiclient\discovery_cache\__init__.py", line 42, in autodetect
    from . import file_cache
  File "C:\Users\Movie Computer\AppData\Local\Programs\Python\Python38\lib\site-packages\googleapiclient\discovery_cache\file_cache.py", line 40, in <module>
    raise ImportError(
ImportError: file_cache is unavailable when using oauth2client >= 4.0.0 or google-auth
2020-07-02 17:17:41,949 - WARNING - file_cache is unavailable when using oauth2client >= 4.0.0 or google-auth
Traceback (most recent call last):
  File "C:\Users\Movie Computer\AppData\Local\Programs\Python\Python38\lib\site-packages\googleapiclient\discovery_cache\__init__.py", line 36, in autodetect
    from google.appengine.api import memcache
ModuleNotFoundError: No module named 'google.appengine'

During handling of the above exception, another exception occurred:

Traceback (most recent call last):
  File "C:\Users\Movie Computer\AppData\Local\Programs\Python\Python38\lib\site-packages\googleapiclient\discovery_cache\file_cache.py", line 33, in <module>
    from oauth2client.contrib.locked_file import LockedFile
ModuleNotFoundError: No module named 'oauth2client.contrib.locked_file'

During handling of the above exception, another exception occurred:

Traceback (most recent call last):
  File "C:\Users\Movie Computer\AppData\Local\Programs\Python\Python38\lib\site-packages\googleapiclient\discovery_cache\file_cache.py", line 37, in <module>
    from oauth2client.locked_file import LockedFile
ModuleNotFoundError: No module named 'oauth2client.locked_file'

During handling of the above exception, another exception occurred:

Traceback (most recent call last):
  File "C:\Users\Movie Computer\AppData\Local\Programs\Python\Python38\lib\site-packages\googleapiclient\discovery_cache\__init__.py", line 42, in autodetect
    from . import file_cache
  File "C:\Users\Movie Computer\AppData\Local\Programs\Python\Python38\lib\site-packages\googleapiclient\discovery_cache\file_cache.py", line 40, in <module>
    raise ImportError(
ImportError: file_cache is unavailable when using oauth2client >= 4.0.0 or google-auth
2020-07-02 17:22:24,555 - WARNING - file_cache is unavailable when using oauth2client >= 4.0.0 or google-auth
Traceback (most recent call last):
  File "C:\Users\Movie Computer\AppData\Local\Programs\Python\Python38\lib\site-packages\googleapiclient\discovery_cache\__init__.py", line 36, in autodetect
    from google.appengine.api import memcache
ModuleNotFoundError: No module named 'google.appengine'

During handling of the above exception, another exception occurred:

Traceback (most recent call last):
  File "C:\Users\Movie Computer\AppData\Local\Programs\Python\Python38\lib\site-packages\googleapiclient\discovery_cache\file_cache.py", line 33, in <module>
    from oauth2client.contrib.locked_file import LockedFile
ModuleNotFoundError: No module named 'oauth2client.contrib.locked_file'

During handling of the above exception, another exception occurred:

Traceback (most recent call last):
  File "C:\Users\Movie Computer\AppData\Local\Programs\Python\Python38\lib\site-packages\googleapiclient\discovery_cache\file_cache.py", line 37, in <module>
    from oauth2client.locked_file import LockedFile
ModuleNotFoundError: No module named 'oauth2client.locked_file'

During handling of the above exception, another exception occurred:

Traceback (most recent call last):
  File "C:\Users\Movie Computer\AppData\Local\Programs\Python\Python38\lib\site-packages\googleapiclient\discovery_cache\__init__.py", line 42, in autodetect
    from . import file_cache
  File "C:\Users\Movie Computer\AppData\Local\Programs\Python\Python38\lib\site-packages\googleapiclient\discovery_cache\file_cache.py", line 40, in <module>
    raise ImportError(
ImportError: file_cache is unavailable when using oauth2client >= 4.0.0 or google-auth
2020-07-02 17:23:39,084 - ERROR - Exception occurred
Traceback (most recent call last):
  File "C:\Users\Movie Computer\Desktop\certification-data-scraper\Scrapers\base_scraper.py", line 48, in run
    self.table_len = len(self.get_table())
  File "C:\Users\Movie Computer\Desktop\certification-data-scraper\Scrapers\Asia\eprocure.py", line 23, in get_table
    table = self.driver.find_element_by_tag_name("tbody")
  File "C:\Users\Movie Computer\AppData\Local\Programs\Python\Python38\lib\site-packages\selenium\webdriver\remote\webdriver.py", line 530, in find_element_by_tag_name
    return self.find_element(by=By.TAG_NAME, value=name)
  File "C:\Users\Movie Computer\AppData\Local\Programs\Python\Python38\lib\site-packages\selenium\webdriver\remote\webdriver.py", line 976, in find_element
    return self.execute(Command.FIND_ELEMENT, {
  File "C:\Users\Movie Computer\AppData\Local\Programs\Python\Python38\lib\site-packages\selenium\webdriver\remote\webdriver.py", line 321, in execute
    self.error_handler.check_response(response)
  File "C:\Users\Movie Computer\AppData\Local\Programs\Python\Python38\lib\site-packages\selenium\webdriver\remote\errorhandler.py", line 242, in check_response
    raise exception_class(message, screen, stacktrace)
selenium.common.exceptions.NoSuchElementException: Message: no such element: Unable to locate element: {"method":"css selector","selector":"tbody"}
  (Session info: chrome=83.0.4103.116)

2020-07-02 17:23:39,099 - WARNING - Retry no. 1
2020-07-02 17:23:39,477 - ERROR - Exception occurred
Traceback (most recent call last):
  File "C:\Users\Movie Computer\Desktop\certification-data-scraper\Scrapers\base_scraper.py", line 48, in run
    self.table_len = len(self.get_table())
  File "C:\Users\Movie Computer\Desktop\certification-data-scraper\Scrapers\Asia\eprocure.py", line 23, in get_table
    table = self.driver.find_element_by_tag_name("tbody")
  File "C:\Users\Movie Computer\AppData\Local\Programs\Python\Python38\lib\site-packages\selenium\webdriver\remote\webdriver.py", line 530, in find_element_by_tag_name
    return self.find_element(by=By.TAG_NAME, value=name)
  File "C:\Users\Movie Computer\AppData\Local\Programs\Python\Python38\lib\site-packages\selenium\webdriver\remote\webdriver.py", line 976, in find_element
    return self.execute(Command.FIND_ELEMENT, {
  File "C:\Users\Movie Computer\AppData\Local\Programs\Python\Python38\lib\site-packages\selenium\webdriver\remote\webdriver.py", line 321, in execute
    self.error_handler.check_response(response)
  File "C:\Users\Movie Computer\AppData\Local\Programs\Python\Python38\lib\site-packages\selenium\webdriver\remote\errorhandler.py", line 242, in check_response
    raise exception_class(message, screen, stacktrace)
selenium.common.exceptions.NoSuchElementException: Message: no such element: Unable to locate element: {"method":"css selector","selector":"tbody"}
  (Session info: chrome=83.0.4103.116)

2020-07-02 17:23:39,483 - WARNING - Retry no. 2
2020-07-02 17:23:39,890 - ERROR - Exception occurred
Traceback (most recent call last):
  File "C:\Users\Movie Computer\Desktop\certification-data-scraper\Scrapers\base_scraper.py", line 48, in run
    self.table_len = len(self.get_table())
  File "C:\Users\Movie Computer\Desktop\certification-data-scraper\Scrapers\Asia\eprocure.py", line 23, in get_table
    table = self.driver.find_element_by_tag_name("tbody")
  File "C:\Users\Movie Computer\AppData\Local\Programs\Python\Python38\lib\site-packages\selenium\webdriver\remote\webdriver.py", line 530, in find_element_by_tag_name
    return self.find_element(by=By.TAG_NAME, value=name)
  File "C:\Users\Movie Computer\AppData\Local\Programs\Python\Python38\lib\site-packages\selenium\webdriver\remote\webdriver.py", line 976, in find_element
    return self.execute(Command.FIND_ELEMENT, {
  File "C:\Users\Movie Computer\AppData\Local\Programs\Python\Python38\lib\site-packages\selenium\webdriver\remote\webdriver.py", line 321, in execute
    self.error_handler.check_response(response)
  File "C:\Users\Movie Computer\AppData\Local\Programs\Python\Python38\lib\site-packages\selenium\webdriver\remote\errorhandler.py", line 242, in check_response
    raise exception_class(message, screen, stacktrace)
selenium.common.exceptions.NoSuchElementException: Message: no such element: Unable to locate element: {"method":"css selector","selector":"tbody"}
  (Session info: chrome=83.0.4103.116)

2020-07-02 17:23:39,897 - WARNING - Retry no. 3
2020-07-02 17:23:40,238 - ERROR - Exception occurred
Traceback (most recent call last):
  File "C:\Users\Movie Computer\Desktop\certification-data-scraper\Scrapers\base_scraper.py", line 48, in run
    self.table_len = len(self.get_table())
  File "C:\Users\Movie Computer\Desktop\certification-data-scraper\Scrapers\Asia\eprocure.py", line 23, in get_table
    table = self.driver.find_element_by_tag_name("tbody")
  File "C:\Users\Movie Computer\AppData\Local\Programs\Python\Python38\lib\site-packages\selenium\webdriver\remote\webdriver.py", line 530, in find_element_by_tag_name
    return self.find_element(by=By.TAG_NAME, value=name)
  File "C:\Users\Movie Computer\AppData\Local\Programs\Python\Python38\lib\site-packages\selenium\webdriver\remote\webdriver.py", line 976, in find_element
    return self.execute(Command.FIND_ELEMENT, {
  File "C:\Users\Movie Computer\AppData\Local\Programs\Python\Python38\lib\site-packages\selenium\webdriver\remote\webdriver.py", line 321, in execute
    self.error_handler.check_response(response)
  File "C:\Users\Movie Computer\AppData\Local\Programs\Python\Python38\lib\site-packages\selenium\webdriver\remote\errorhandler.py", line 242, in check_response
    raise exception_class(message, screen, stacktrace)
selenium.common.exceptions.NoSuchElementException: Message: no such element: Unable to locate element: {"method":"css selector","selector":"tbody"}
  (Session info: chrome=83.0.4103.116)

2020-07-02 17:23:40,245 - WARNING - Retry no. 4
2020-07-02 17:23:40,552 - ERROR - Exception occurred
Traceback (most recent call last):
  File "C:\Users\Movie Computer\Desktop\certification-data-scraper\Scrapers\base_scraper.py", line 48, in run
    self.table_len = len(self.get_table())
  File "C:\Users\Movie Computer\Desktop\certification-data-scraper\Scrapers\Asia\eprocure.py", line 23, in get_table
    table = self.driver.find_element_by_tag_name("tbody")
  File "C:\Users\Movie Computer\AppData\Local\Programs\Python\Python38\lib\site-packages\selenium\webdriver\remote\webdriver.py", line 530, in find_element_by_tag_name
    return self.find_element(by=By.TAG_NAME, value=name)
  File "C:\Users\Movie Computer\AppData\Local\Programs\Python\Python38\lib\site-packages\selenium\webdriver\remote\webdriver.py", line 976, in find_element
    return self.execute(Command.FIND_ELEMENT, {
  File "C:\Users\Movie Computer\AppData\Local\Programs\Python\Python38\lib\site-packages\selenium\webdriver\remote\webdriver.py", line 321, in execute
    self.error_handler.check_response(response)
  File "C:\Users\Movie Computer\AppData\Local\Programs\Python\Python38\lib\site-packages\selenium\webdriver\remote\errorhandler.py", line 242, in check_response
    raise exception_class(message, screen, stacktrace)
selenium.common.exceptions.NoSuchElementException: Message: no such element: Unable to locate element: {"method":"css selector","selector":"tbody"}
  (Session info: chrome=83.0.4103.116)

2020-07-02 17:23:40,559 - WARNING - Retry no. 5
2020-07-02 17:23:40,560 - WARNING - Maximum retries exceeded, quitting program and saving logs.
2020-07-02 17:24:55,351 - ERROR - Exception occurred
Traceback (most recent call last):
  File "C:\Users\Movie Computer\Desktop\certification-data-scraper\Scrapers\base_scraper.py", line 54, in run
    self.data_list.append(self.click_links())
  File "C:\Users\Movie Computer\Desktop\certification-data-scraper\Scrapers\Asia\eprocure.py", line 33, in click_links
    data = self.get_data()
  File "C:\Users\Movie Computer\Desktop\certification-data-scraper\Scrapers\Asia\eprocure.py", line 47, in get_data
    info_list.append(soup.find('td', string="ePublished Date").find_next_siblings(width="20%")[0].text.strip())
AttributeError: 'NoneType' object has no attribute 'find_next_siblings'
2020-07-02 17:24:55,372 - WARNING - Retry no. 1
2020-07-02 17:26:32,747 - WARNING - file_cache is unavailable when using oauth2client >= 4.0.0 or google-auth
Traceback (most recent call last):
  File "C:\Users\Movie Computer\AppData\Local\Programs\Python\Python38\lib\site-packages\googleapiclient\discovery_cache\__init__.py", line 36, in autodetect
    from google.appengine.api import memcache
ModuleNotFoundError: No module named 'google.appengine'

During handling of the above exception, another exception occurred:

Traceback (most recent call last):
  File "C:\Users\Movie Computer\AppData\Local\Programs\Python\Python38\lib\site-packages\googleapiclient\discovery_cache\file_cache.py", line 33, in <module>
    from oauth2client.contrib.locked_file import LockedFile
ModuleNotFoundError: No module named 'oauth2client.contrib.locked_file'

During handling of the above exception, another exception occurred:

Traceback (most recent call last):
  File "C:\Users\Movie Computer\AppData\Local\Programs\Python\Python38\lib\site-packages\googleapiclient\discovery_cache\file_cache.py", line 37, in <module>
    from oauth2client.locked_file import LockedFile
ModuleNotFoundError: No module named 'oauth2client.locked_file'

During handling of the above exception, another exception occurred:

Traceback (most recent call last):
  File "C:\Users\Movie Computer\AppData\Local\Programs\Python\Python38\lib\site-packages\googleapiclient\discovery_cache\__init__.py", line 42, in autodetect
    from . import file_cache
  File "C:\Users\Movie Computer\AppData\Local\Programs\Python\Python38\lib\site-packages\googleapiclient\discovery_cache\file_cache.py", line 40, in <module>
    raise ImportError(
ImportError: file_cache is unavailable when using oauth2client >= 4.0.0 or google-auth
2020-07-02 17:28:08,315 - ERROR - Exception occurred
Traceback (most recent call last):
  File "C:\Users\Movie Computer\Desktop\certification-data-scraper\Scrapers\Asia\eprocure.py", line 90, in download
    self.driver.find_element_by_xpath("//*[contains(text(), 'Download as zip file')]").click()
  File "C:\Users\Movie Computer\AppData\Local\Programs\Python\Python38\lib\site-packages\selenium\webdriver\remote\webdriver.py", line 394, in find_element_by_xpath
    return self.find_element(by=By.XPATH, value=xpath)
  File "C:\Users\Movie Computer\AppData\Local\Programs\Python\Python38\lib\site-packages\selenium\webdriver\remote\webdriver.py", line 976, in find_element
    return self.execute(Command.FIND_ELEMENT, {
  File "C:\Users\Movie Computer\AppData\Local\Programs\Python\Python38\lib\site-packages\selenium\webdriver\remote\webdriver.py", line 321, in execute
    self.error_handler.check_response(response)
  File "C:\Users\Movie Computer\AppData\Local\Programs\Python\Python38\lib\site-packages\selenium\webdriver\remote\errorhandler.py", line 242, in check_response
    raise exception_class(message, screen, stacktrace)
selenium.common.exceptions.NoSuchElementException: Message: no such element: Unable to locate element: {"method":"xpath","selector":"//*[contains(text(), 'Download as zip file')]"}
  (Session info: chrome=83.0.4103.116)

2020-07-02 17:28:08,331 - WARNING - file_cache is unavailable when using oauth2client >= 4.0.0 or google-auth
Traceback (most recent call last):
  File "C:\Users\Movie Computer\AppData\Local\Programs\Python\Python38\lib\site-packages\googleapiclient\discovery_cache\__init__.py", line 36, in autodetect
    from google.appengine.api import memcache
ModuleNotFoundError: No module named 'google.appengine'

During handling of the above exception, another exception occurred:

Traceback (most recent call last):
  File "C:\Users\Movie Computer\AppData\Local\Programs\Python\Python38\lib\site-packages\googleapiclient\discovery_cache\file_cache.py", line 33, in <module>
    from oauth2client.contrib.locked_file import LockedFile
ModuleNotFoundError: No module named 'oauth2client.contrib.locked_file'

During handling of the above exception, another exception occurred:

Traceback (most recent call last):
  File "C:\Users\Movie Computer\AppData\Local\Programs\Python\Python38\lib\site-packages\googleapiclient\discovery_cache\file_cache.py", line 37, in <module>
    from oauth2client.locked_file import LockedFile
ModuleNotFoundError: No module named 'oauth2client.locked_file'

During handling of the above exception, another exception occurred:

Traceback (most recent call last):
  File "C:\Users\Movie Computer\AppData\Local\Programs\Python\Python38\lib\site-packages\googleapiclient\discovery_cache\__init__.py", line 42, in autodetect
    from . import file_cache
  File "C:\Users\Movie Computer\AppData\Local\Programs\Python\Python38\lib\site-packages\googleapiclient\discovery_cache\file_cache.py", line 40, in <module>
    raise ImportError(
ImportError: file_cache is unavailable when using oauth2client >= 4.0.0 or google-auth
2020-07-02 17:31:51,134 - ERROR - Exception occurred
Traceback (most recent call last):
  File "C:\Users\Movie Computer\Desktop\certification-data-scraper\Scrapers\base_scraper.py", line 48, in run
    self.table_len = len(self.get_table())
  File "C:\Users\Movie Computer\Desktop\certification-data-scraper\Scrapers\Asia\eprocure.py", line 23, in get_table
    table = self.driver.find_element_by_tag_name("tbody")
  File "C:\Users\Movie Computer\AppData\Local\Programs\Python\Python38\lib\site-packages\selenium\webdriver\remote\webdriver.py", line 530, in find_element_by_tag_name
    return self.find_element(by=By.TAG_NAME, value=name)
  File "C:\Users\Movie Computer\AppData\Local\Programs\Python\Python38\lib\site-packages\selenium\webdriver\remote\webdriver.py", line 976, in find_element
    return self.execute(Command.FIND_ELEMENT, {
  File "C:\Users\Movie Computer\AppData\Local\Programs\Python\Python38\lib\site-packages\selenium\webdriver\remote\webdriver.py", line 321, in execute
    self.error_handler.check_response(response)
  File "C:\Users\Movie Computer\AppData\Local\Programs\Python\Python38\lib\site-packages\selenium\webdriver\remote\errorhandler.py", line 242, in check_response
    raise exception_class(message, screen, stacktrace)
selenium.common.exceptions.NoSuchElementException: Message: no such element: Unable to locate element: {"method":"css selector","selector":"tbody"}
  (Session info: chrome=83.0.4103.116)

2020-07-02 17:31:51,146 - WARNING - Retry no. 2
2020-07-02 17:31:51,961 - ERROR - Exception occurred
Traceback (most recent call last):
  File "C:\Users\Movie Computer\Desktop\certification-data-scraper\Scrapers\base_scraper.py", line 48, in run
    self.table_len = len(self.get_table())
  File "C:\Users\Movie Computer\Desktop\certification-data-scraper\Scrapers\Asia\eprocure.py", line 23, in get_table
    table = self.driver.find_element_by_tag_name("tbody")
  File "C:\Users\Movie Computer\AppData\Local\Programs\Python\Python38\lib\site-packages\selenium\webdriver\remote\webdriver.py", line 530, in find_element_by_tag_name
    return self.find_element(by=By.TAG_NAME, value=name)
  File "C:\Users\Movie Computer\AppData\Local\Programs\Python\Python38\lib\site-packages\selenium\webdriver\remote\webdriver.py", line 976, in find_element
    return self.execute(Command.FIND_ELEMENT, {
  File "C:\Users\Movie Computer\AppData\Local\Programs\Python\Python38\lib\site-packages\selenium\webdriver\remote\webdriver.py", line 321, in execute
    self.error_handler.check_response(response)
  File "C:\Users\Movie Computer\AppData\Local\Programs\Python\Python38\lib\site-packages\selenium\webdriver\remote\errorhandler.py", line 242, in check_response
    raise exception_class(message, screen, stacktrace)
selenium.common.exceptions.NoSuchElementException: Message: no such element: Unable to locate element: {"method":"css selector","selector":"tbody"}
  (Session info: chrome=83.0.4103.116)

2020-07-02 17:31:51,968 - WARNING - Retry no. 3
2020-07-02 17:31:52,550 - ERROR - Exception occurred
Traceback (most recent call last):
  File "C:\Users\Movie Computer\Desktop\certification-data-scraper\Scrapers\base_scraper.py", line 48, in run
    self.table_len = len(self.get_table())
  File "C:\Users\Movie Computer\Desktop\certification-data-scraper\Scrapers\Asia\eprocure.py", line 23, in get_table
    table = self.driver.find_element_by_tag_name("tbody")
  File "C:\Users\Movie Computer\AppData\Local\Programs\Python\Python38\lib\site-packages\selenium\webdriver\remote\webdriver.py", line 530, in find_element_by_tag_name
    return self.find_element(by=By.TAG_NAME, value=name)
  File "C:\Users\Movie Computer\AppData\Local\Programs\Python\Python38\lib\site-packages\selenium\webdriver\remote\webdriver.py", line 976, in find_element
    return self.execute(Command.FIND_ELEMENT, {
  File "C:\Users\Movie Computer\AppData\Local\Programs\Python\Python38\lib\site-packages\selenium\webdriver\remote\webdriver.py", line 321, in execute
    self.error_handler.check_response(response)
  File "C:\Users\Movie Computer\AppData\Local\Programs\Python\Python38\lib\site-packages\selenium\webdriver\remote\errorhandler.py", line 242, in check_response
    raise exception_class(message, screen, stacktrace)
selenium.common.exceptions.NoSuchElementException: Message: no such element: Unable to locate element: {"method":"css selector","selector":"tbody"}
  (Session info: chrome=83.0.4103.116)

2020-07-02 17:31:52,557 - WARNING - Retry no. 4
2020-07-02 17:31:53,144 - ERROR - Exception occurred
Traceback (most recent call last):
  File "C:\Users\Movie Computer\Desktop\certification-data-scraper\Scrapers\base_scraper.py", line 48, in run
    self.table_len = len(self.get_table())
  File "C:\Users\Movie Computer\Desktop\certification-data-scraper\Scrapers\Asia\eprocure.py", line 23, in get_table
    table = self.driver.find_element_by_tag_name("tbody")
  File "C:\Users\Movie Computer\AppData\Local\Programs\Python\Python38\lib\site-packages\selenium\webdriver\remote\webdriver.py", line 530, in find_element_by_tag_name
    return self.find_element(by=By.TAG_NAME, value=name)
  File "C:\Users\Movie Computer\AppData\Local\Programs\Python\Python38\lib\site-packages\selenium\webdriver\remote\webdriver.py", line 976, in find_element
    return self.execute(Command.FIND_ELEMENT, {
  File "C:\Users\Movie Computer\AppData\Local\Programs\Python\Python38\lib\site-packages\selenium\webdriver\remote\webdriver.py", line 321, in execute
    self.error_handler.check_response(response)
  File "C:\Users\Movie Computer\AppData\Local\Programs\Python\Python38\lib\site-packages\selenium\webdriver\remote\errorhandler.py", line 242, in check_response
    raise exception_class(message, screen, stacktrace)
selenium.common.exceptions.NoSuchElementException: Message: no such element: Unable to locate element: {"method":"css selector","selector":"tbody"}
  (Session info: chrome=83.0.4103.116)

2020-07-02 17:31:53,154 - WARNING - Retry no. 5
2020-07-02 17:31:53,154 - WARNING - Maximum retries exceeded, quitting program and saving logs.
2020-07-02 17:37:46,731 - ERROR - Exception occurred
Traceback (most recent call last):
  File "C:\Users\Movie Computer\Desktop\certification-data-scraper\Scrapers\base_scraper.py", line 54, in run
    self.data_list.append(self.click_links())
  File "C:\Users\Movie Computer\Desktop\certification-data-scraper\Scrapers\Asia\eprocure.py", line 33, in click_links
    data = self.get_data()
  File "C:\Users\Movie Computer\Desktop\certification-data-scraper\Scrapers\Asia\eprocure.py", line 47, in get_data
    info_list.append(soup.find('td', string="ePublished Date").find_next_siblings(width="20%")[0].text.strip())
AttributeError: 'NoneType' object has no attribute 'find_next_siblings'
2020-07-02 17:37:46,743 - WARNING - Retry no. 1
2020-07-02 17:37:53,560 - ERROR - Exception occurred
Traceback (most recent call last):
  File "C:\Users\Movie Computer\Desktop\certification-data-scraper\Scrapers\base_scraper.py", line 54, in run
    self.data_list.append(self.click_links())
  File "C:\Users\Movie Computer\Desktop\certification-data-scraper\Scrapers\Asia\eprocure.py", line 30, in click_links
    columns[4].find_element_by_tag_name("a").click()
IndexError: list index out of range
2020-07-02 17:37:53,566 - WARNING - Retry no. 2
2020-07-02 17:39:28,917 - WARNING - file_cache is unavailable when using oauth2client >= 4.0.0 or google-auth
Traceback (most recent call last):
  File "C:\Users\Movie Computer\AppData\Local\Programs\Python\Python38\lib\site-packages\googleapiclient\discovery_cache\__init__.py", line 36, in autodetect
    from google.appengine.api import memcache
ModuleNotFoundError: No module named 'google.appengine'

During handling of the above exception, another exception occurred:

Traceback (most recent call last):
  File "C:\Users\Movie Computer\AppData\Local\Programs\Python\Python38\lib\site-packages\googleapiclient\discovery_cache\file_cache.py", line 33, in <module>
    from oauth2client.contrib.locked_file import LockedFile
ModuleNotFoundError: No module named 'oauth2client.contrib.locked_file'

During handling of the above exception, another exception occurred:

Traceback (most recent call last):
  File "C:\Users\Movie Computer\AppData\Local\Programs\Python\Python38\lib\site-packages\googleapiclient\discovery_cache\file_cache.py", line 37, in <module>
    from oauth2client.locked_file import LockedFile
ModuleNotFoundError: No module named 'oauth2client.locked_file'

During handling of the above exception, another exception occurred:

Traceback (most recent call last):
  File "C:\Users\Movie Computer\AppData\Local\Programs\Python\Python38\lib\site-packages\googleapiclient\discovery_cache\__init__.py", line 42, in autodetect
    from . import file_cache
  File "C:\Users\Movie Computer\AppData\Local\Programs\Python\Python38\lib\site-packages\googleapiclient\discovery_cache\file_cache.py", line 40, in <module>
    raise ImportError(
ImportError: file_cache is unavailable when using oauth2client >= 4.0.0 or google-auth
2020-07-02 17:43:12,301 - WARNING - file_cache is unavailable when using oauth2client >= 4.0.0 or google-auth
Traceback (most recent call last):
  File "C:\Users\Movie Computer\AppData\Local\Programs\Python\Python38\lib\site-packages\googleapiclient\discovery_cache\__init__.py", line 36, in autodetect
    from google.appengine.api import memcache
ModuleNotFoundError: No module named 'google.appengine'

During handling of the above exception, another exception occurred:

Traceback (most recent call last):
  File "C:\Users\Movie Computer\AppData\Local\Programs\Python\Python38\lib\site-packages\googleapiclient\discovery_cache\file_cache.py", line 33, in <module>
    from oauth2client.contrib.locked_file import LockedFile
ModuleNotFoundError: No module named 'oauth2client.contrib.locked_file'

During handling of the above exception, another exception occurred:

Traceback (most recent call last):
  File "C:\Users\Movie Computer\AppData\Local\Programs\Python\Python38\lib\site-packages\googleapiclient\discovery_cache\file_cache.py", line 37, in <module>
    from oauth2client.locked_file import LockedFile
ModuleNotFoundError: No module named 'oauth2client.locked_file'

During handling of the above exception, another exception occurred:

Traceback (most recent call last):
  File "C:\Users\Movie Computer\AppData\Local\Programs\Python\Python38\lib\site-packages\googleapiclient\discovery_cache\__init__.py", line 42, in autodetect
    from . import file_cache
  File "C:\Users\Movie Computer\AppData\Local\Programs\Python\Python38\lib\site-packages\googleapiclient\discovery_cache\file_cache.py", line 40, in <module>
    raise ImportError(
ImportError: file_cache is unavailable when using oauth2client >= 4.0.0 or google-auth
2020-07-02 17:44:24,129 - ERROR - Exception occurred
Traceback (most recent call last):
  File "C:\Users\Movie Computer\Desktop\certification-data-scraper\Scrapers\Asia\eprocure.py", line 83, in download
    self.driver.find_element_by_xpath("//button[@id='captcha']")
  File "C:\Users\Movie Computer\AppData\Local\Programs\Python\Python38\lib\site-packages\selenium\webdriver\remote\webdriver.py", line 394, in find_element_by_xpath
    return self.find_element(by=By.XPATH, value=xpath)
  File "C:\Users\Movie Computer\AppData\Local\Programs\Python\Python38\lib\site-packages\selenium\webdriver\remote\webdriver.py", line 976, in find_element
    return self.execute(Command.FIND_ELEMENT, {
  File "C:\Users\Movie Computer\AppData\Local\Programs\Python\Python38\lib\site-packages\selenium\webdriver\remote\webdriver.py", line 321, in execute
    self.error_handler.check_response(response)
  File "C:\Users\Movie Computer\AppData\Local\Programs\Python\Python38\lib\site-packages\selenium\webdriver\remote\errorhandler.py", line 242, in check_response
    raise exception_class(message, screen, stacktrace)
selenium.common.exceptions.NoSuchElementException: Message: no such element: Unable to locate element: {"method":"xpath","selector":"//button[@id='captcha']"}
  (Session info: chrome=83.0.4103.116)

2020-07-02 17:46:34,463 - WARNING - file_cache is unavailable when using oauth2client >= 4.0.0 or google-auth
Traceback (most recent call last):
  File "C:\Users\Movie Computer\AppData\Local\Programs\Python\Python38\lib\site-packages\googleapiclient\discovery_cache\__init__.py", line 36, in autodetect
    from google.appengine.api import memcache
ModuleNotFoundError: No module named 'google.appengine'

During handling of the above exception, another exception occurred:

Traceback (most recent call last):
  File "C:\Users\Movie Computer\AppData\Local\Programs\Python\Python38\lib\site-packages\googleapiclient\discovery_cache\file_cache.py", line 33, in <module>
    from oauth2client.contrib.locked_file import LockedFile
ModuleNotFoundError: No module named 'oauth2client.contrib.locked_file'

During handling of the above exception, another exception occurred:

Traceback (most recent call last):
  File "C:\Users\Movie Computer\AppData\Local\Programs\Python\Python38\lib\site-packages\googleapiclient\discovery_cache\file_cache.py", line 37, in <module>
    from oauth2client.locked_file import LockedFile
ModuleNotFoundError: No module named 'oauth2client.locked_file'

During handling of the above exception, another exception occurred:

Traceback (most recent call last):
  File "C:\Users\Movie Computer\AppData\Local\Programs\Python\Python38\lib\site-packages\googleapiclient\discovery_cache\__init__.py", line 42, in autodetect
    from . import file_cache
  File "C:\Users\Movie Computer\AppData\Local\Programs\Python\Python38\lib\site-packages\googleapiclient\discovery_cache\file_cache.py", line 40, in <module>
    raise ImportError(
ImportError: file_cache is unavailable when using oauth2client >= 4.0.0 or google-auth
2020-07-02 17:47:44,803 - ERROR - Exception occurred
Traceback (most recent call last):
  File "C:\Users\Movie Computer\Desktop\certification-data-scraper\Scrapers\Asia\eprocure.py", line 83, in download
    self.driver.find_element_by_xpath("//button[@id='captcha']")
  File "C:\Users\Movie Computer\AppData\Local\Programs\Python\Python38\lib\site-packages\selenium\webdriver\remote\webdriver.py", line 394, in find_element_by_xpath
    return self.find_element(by=By.XPATH, value=xpath)
  File "C:\Users\Movie Computer\AppData\Local\Programs\Python\Python38\lib\site-packages\selenium\webdriver\remote\webdriver.py", line 976, in find_element
    return self.execute(Command.FIND_ELEMENT, {
  File "C:\Users\Movie Computer\AppData\Local\Programs\Python\Python38\lib\site-packages\selenium\webdriver\remote\webdriver.py", line 321, in execute
    self.error_handler.check_response(response)
  File "C:\Users\Movie Computer\AppData\Local\Programs\Python\Python38\lib\site-packages\selenium\webdriver\remote\errorhandler.py", line 242, in check_response
    raise exception_class(message, screen, stacktrace)
selenium.common.exceptions.NoSuchElementException: Message: no such element: Unable to locate element: {"method":"xpath","selector":"//button[@id='captcha']"}
  (Session info: chrome=83.0.4103.116)

2020-07-02 17:49:56,224 - WARNING - file_cache is unavailable when using oauth2client >= 4.0.0 or google-auth
Traceback (most recent call last):
  File "C:\Users\Movie Computer\AppData\Local\Programs\Python\Python38\lib\site-packages\googleapiclient\discovery_cache\__init__.py", line 36, in autodetect
    from google.appengine.api import memcache
ModuleNotFoundError: No module named 'google.appengine'

During handling of the above exception, another exception occurred:

Traceback (most recent call last):
  File "C:\Users\Movie Computer\AppData\Local\Programs\Python\Python38\lib\site-packages\googleapiclient\discovery_cache\file_cache.py", line 33, in <module>
    from oauth2client.contrib.locked_file import LockedFile
ModuleNotFoundError: No module named 'oauth2client.contrib.locked_file'

During handling of the above exception, another exception occurred:

Traceback (most recent call last):
  File "C:\Users\Movie Computer\AppData\Local\Programs\Python\Python38\lib\site-packages\googleapiclient\discovery_cache\file_cache.py", line 37, in <module>
    from oauth2client.locked_file import LockedFile
ModuleNotFoundError: No module named 'oauth2client.locked_file'

During handling of the above exception, another exception occurred:

Traceback (most recent call last):
  File "C:\Users\Movie Computer\AppData\Local\Programs\Python\Python38\lib\site-packages\googleapiclient\discovery_cache\__init__.py", line 42, in autodetect
    from . import file_cache
  File "C:\Users\Movie Computer\AppData\Local\Programs\Python\Python38\lib\site-packages\googleapiclient\discovery_cache\file_cache.py", line 40, in <module>
    raise ImportError(
ImportError: file_cache is unavailable when using oauth2client >= 4.0.0 or google-auth
2020-07-02 17:51:08,927 - ERROR - Exception occurred
Traceback (most recent call last):
  File "C:\Users\Movie Computer\Desktop\certification-data-scraper\Scrapers\Asia\eprocure.py", line 83, in download
    self.driver.find_element_by_xpath("//button[@id='captcha']")
  File "C:\Users\Movie Computer\AppData\Local\Programs\Python\Python38\lib\site-packages\selenium\webdriver\remote\webdriver.py", line 394, in find_element_by_xpath
    return self.find_element(by=By.XPATH, value=xpath)
  File "C:\Users\Movie Computer\AppData\Local\Programs\Python\Python38\lib\site-packages\selenium\webdriver\remote\webdriver.py", line 976, in find_element
    return self.execute(Command.FIND_ELEMENT, {
  File "C:\Users\Movie Computer\AppData\Local\Programs\Python\Python38\lib\site-packages\selenium\webdriver\remote\webdriver.py", line 321, in execute
    self.error_handler.check_response(response)
  File "C:\Users\Movie Computer\AppData\Local\Programs\Python\Python38\lib\site-packages\selenium\webdriver\remote\errorhandler.py", line 242, in check_response
    raise exception_class(message, screen, stacktrace)
selenium.common.exceptions.NoSuchElementException: Message: no such element: Unable to locate element: {"method":"xpath","selector":"//button[@id='captcha']"}
  (Session info: chrome=83.0.4103.116)

2020-07-02 17:53:23,007 - WARNING - file_cache is unavailable when using oauth2client >= 4.0.0 or google-auth
Traceback (most recent call last):
  File "C:\Users\Movie Computer\AppData\Local\Programs\Python\Python38\lib\site-packages\googleapiclient\discovery_cache\__init__.py", line 36, in autodetect
    from google.appengine.api import memcache
ModuleNotFoundError: No module named 'google.appengine'

During handling of the above exception, another exception occurred:

Traceback (most recent call last):
  File "C:\Users\Movie Computer\AppData\Local\Programs\Python\Python38\lib\site-packages\googleapiclient\discovery_cache\file_cache.py", line 33, in <module>
    from oauth2client.contrib.locked_file import LockedFile
ModuleNotFoundError: No module named 'oauth2client.contrib.locked_file'

During handling of the above exception, another exception occurred:

Traceback (most recent call last):
  File "C:\Users\Movie Computer\AppData\Local\Programs\Python\Python38\lib\site-packages\googleapiclient\discovery_cache\file_cache.py", line 37, in <module>
    from oauth2client.locked_file import LockedFile
ModuleNotFoundError: No module named 'oauth2client.locked_file'

During handling of the above exception, another exception occurred:

Traceback (most recent call last):
  File "C:\Users\Movie Computer\AppData\Local\Programs\Python\Python38\lib\site-packages\googleapiclient\discovery_cache\__init__.py", line 42, in autodetect
    from . import file_cache
  File "C:\Users\Movie Computer\AppData\Local\Programs\Python\Python38\lib\site-packages\googleapiclient\discovery_cache\file_cache.py", line 40, in <module>
    raise ImportError(
ImportError: file_cache is unavailable when using oauth2client >= 4.0.0 or google-auth
2020-07-02 17:54:38,904 - ERROR - Exception occurred
Traceback (most recent call last):
  File "C:\Users\Movie Computer\Desktop\certification-data-scraper\Scrapers\base_scraper.py", line 54, in run
    self.data_list.append(self.click_links())
  File "C:\Users\Movie Computer\Desktop\certification-data-scraper\Scrapers\Asia\eprocure.py", line 33, in click_links
    data = self.get_data()
  File "C:\Users\Movie Computer\Desktop\certification-data-scraper\Scrapers\Asia\eprocure.py", line 45, in get_data
    soup = BeautifulSoup(self.driver.page_source, 'html.parser')
  File "C:\Users\Movie Computer\AppData\Local\Programs\Python\Python38\lib\site-packages\selenium\webdriver\remote\webdriver.py", line 679, in page_source
    return self.execute(Command.GET_PAGE_SOURCE)['value']
  File "C:\Users\Movie Computer\AppData\Local\Programs\Python\Python38\lib\site-packages\selenium\webdriver\remote\webdriver.py", line 321, in execute
    self.error_handler.check_response(response)
  File "C:\Users\Movie Computer\AppData\Local\Programs\Python\Python38\lib\site-packages\selenium\webdriver\remote\errorhandler.py", line 242, in check_response
    raise exception_class(message, screen, stacktrace)
selenium.common.exceptions.WebDriverException: Message: chrome not reachable
  (Session info: chrome=83.0.4103.116)

2020-07-02 17:54:38,904 - WARNING - Retry no. 3
2020-07-02 17:54:51,100 - ERROR - Exception occurred
Traceback (most recent call last):
  File "C:\Users\Movie Computer\Desktop\certification-data-scraper\Scrapers\base_scraper.py", line 39, in run
    self.driver.get(self.link)
  File "C:\Users\Movie Computer\AppData\Local\Programs\Python\Python38\lib\site-packages\selenium\webdriver\remote\webdriver.py", line 333, in get
    self.execute(Command.GET, {'url': url})
  File "C:\Users\Movie Computer\AppData\Local\Programs\Python\Python38\lib\site-packages\selenium\webdriver\remote\webdriver.py", line 321, in execute
    self.error_handler.check_response(response)
  File "C:\Users\Movie Computer\AppData\Local\Programs\Python\Python38\lib\site-packages\selenium\webdriver\remote\errorhandler.py", line 242, in check_response
    raise exception_class(message, screen, stacktrace)
selenium.common.exceptions.WebDriverException: Message: chrome not reachable
  (Session info: chrome=83.0.4103.116)

2020-07-02 17:54:51,100 - WARNING - Retry no. 4
2020-07-02 17:55:03,428 - ERROR - Exception occurred
Traceback (most recent call last):
  File "C:\Users\Movie Computer\Desktop\certification-data-scraper\Scrapers\base_scraper.py", line 39, in run
    self.driver.get(self.link)
  File "C:\Users\Movie Computer\AppData\Local\Programs\Python\Python38\lib\site-packages\selenium\webdriver\remote\webdriver.py", line 333, in get
    self.execute(Command.GET, {'url': url})
  File "C:\Users\Movie Computer\AppData\Local\Programs\Python\Python38\lib\site-packages\selenium\webdriver\remote\webdriver.py", line 321, in execute
    self.error_handler.check_response(response)
  File "C:\Users\Movie Computer\AppData\Local\Programs\Python\Python38\lib\site-packages\selenium\webdriver\remote\errorhandler.py", line 242, in check_response
    raise exception_class(message, screen, stacktrace)
selenium.common.exceptions.WebDriverException: Message: chrome not reachable
  (Session info: chrome=83.0.4103.116)

2020-07-02 17:55:03,428 - WARNING - Retry no. 5
2020-07-02 17:55:03,428 - WARNING - Maximum retries exceeded, quitting program and saving logs.
2020-07-02 17:56:58,317 - WARNING - file_cache is unavailable when using oauth2client >= 4.0.0 or google-auth
Traceback (most recent call last):
  File "C:\Users\Movie Computer\AppData\Local\Programs\Python\Python38\lib\site-packages\googleapiclient\discovery_cache\__init__.py", line 36, in autodetect
    from google.appengine.api import memcache
ModuleNotFoundError: No module named 'google.appengine'

During handling of the above exception, another exception occurred:

Traceback (most recent call last):
  File "C:\Users\Movie Computer\AppData\Local\Programs\Python\Python38\lib\site-packages\googleapiclient\discovery_cache\file_cache.py", line 33, in <module>
    from oauth2client.contrib.locked_file import LockedFile
ModuleNotFoundError: No module named 'oauth2client.contrib.locked_file'

During handling of the above exception, another exception occurred:

Traceback (most recent call last):
  File "C:\Users\Movie Computer\AppData\Local\Programs\Python\Python38\lib\site-packages\googleapiclient\discovery_cache\file_cache.py", line 37, in <module>
    from oauth2client.locked_file import LockedFile
ModuleNotFoundError: No module named 'oauth2client.locked_file'

During handling of the above exception, another exception occurred:

Traceback (most recent call last):
  File "C:\Users\Movie Computer\AppData\Local\Programs\Python\Python38\lib\site-packages\googleapiclient\discovery_cache\__init__.py", line 42, in autodetect
    from . import file_cache
  File "C:\Users\Movie Computer\AppData\Local\Programs\Python\Python38\lib\site-packages\googleapiclient\discovery_cache\file_cache.py", line 40, in <module>
    raise ImportError(
ImportError: file_cache is unavailable when using oauth2client >= 4.0.0 or google-auth
2020-07-02 18:00:55,775 - WARNING - file_cache is unavailable when using oauth2client >= 4.0.0 or google-auth
Traceback (most recent call last):
  File "C:\Users\Movie Computer\AppData\Local\Programs\Python\Python38\lib\site-packages\googleapiclient\discovery_cache\__init__.py", line 36, in autodetect
    from google.appengine.api import memcache
ModuleNotFoundError: No module named 'google.appengine'

During handling of the above exception, another exception occurred:

Traceback (most recent call last):
  File "C:\Users\Movie Computer\AppData\Local\Programs\Python\Python38\lib\site-packages\googleapiclient\discovery_cache\file_cache.py", line 33, in <module>
    from oauth2client.contrib.locked_file import LockedFile
ModuleNotFoundError: No module named 'oauth2client.contrib.locked_file'

During handling of the above exception, another exception occurred:

Traceback (most recent call last):
  File "C:\Users\Movie Computer\AppData\Local\Programs\Python\Python38\lib\site-packages\googleapiclient\discovery_cache\file_cache.py", line 37, in <module>
    from oauth2client.locked_file import LockedFile
ModuleNotFoundError: No module named 'oauth2client.locked_file'

During handling of the above exception, another exception occurred:

Traceback (most recent call last):
  File "C:\Users\Movie Computer\AppData\Local\Programs\Python\Python38\lib\site-packages\googleapiclient\discovery_cache\__init__.py", line 42, in autodetect
    from . import file_cache
  File "C:\Users\Movie Computer\AppData\Local\Programs\Python\Python38\lib\site-packages\googleapiclient\discovery_cache\file_cache.py", line 40, in <module>
    raise ImportError(
ImportError: file_cache is unavailable when using oauth2client >= 4.0.0 or google-auth
2020-07-02 18:01:57,159 - ERROR - Exception occurred
Traceback (most recent call last):
  File "C:\Users\Movie Computer\Desktop\certification-data-scraper\Scrapers\base_scraper.py", line 55, in run
    self.data_list.append(self.click_links())
  File "C:\Users\Movie Computer\Desktop\certification-data-scraper\Scrapers\Asia\eprocure.py", line 33, in click_links
    data = self.get_data()
  File "C:\Users\Movie Computer\Desktop\certification-data-scraper\Scrapers\Asia\eprocure.py", line 47, in get_data
    info_list.append(soup.find('td', string="ePublished Date").find_next_siblings(width="20%")[0].text.strip())
AttributeError: 'NoneType' object has no attribute 'find_next_siblings'
2020-07-02 18:01:57,172 - WARNING - Retry no. 1
2020-07-02 18:05:07,266 - WARNING - file_cache is unavailable when using oauth2client >= 4.0.0 or google-auth
Traceback (most recent call last):
  File "C:\Users\Movie Computer\AppData\Local\Programs\Python\Python38\lib\site-packages\googleapiclient\discovery_cache\__init__.py", line 36, in autodetect
    from google.appengine.api import memcache
ModuleNotFoundError: No module named 'google.appengine'

During handling of the above exception, another exception occurred:

Traceback (most recent call last):
  File "C:\Users\Movie Computer\AppData\Local\Programs\Python\Python38\lib\site-packages\googleapiclient\discovery_cache\file_cache.py", line 33, in <module>
    from oauth2client.contrib.locked_file import LockedFile
ModuleNotFoundError: No module named 'oauth2client.contrib.locked_file'

During handling of the above exception, another exception occurred:

Traceback (most recent call last):
  File "C:\Users\Movie Computer\AppData\Local\Programs\Python\Python38\lib\site-packages\googleapiclient\discovery_cache\file_cache.py", line 37, in <module>
    from oauth2client.locked_file import LockedFile
ModuleNotFoundError: No module named 'oauth2client.locked_file'

During handling of the above exception, another exception occurred:

Traceback (most recent call last):
  File "C:\Users\Movie Computer\AppData\Local\Programs\Python\Python38\lib\site-packages\googleapiclient\discovery_cache\__init__.py", line 42, in autodetect
    from . import file_cache
  File "C:\Users\Movie Computer\AppData\Local\Programs\Python\Python38\lib\site-packages\googleapiclient\discovery_cache\file_cache.py", line 40, in <module>
    raise ImportError(
ImportError: file_cache is unavailable when using oauth2client >= 4.0.0 or google-auth
2020-07-02 18:06:51,480 - ERROR - Exception occurred
Traceback (most recent call last):
  File "C:\Users\Movie Computer\Desktop\certification-data-scraper\Scrapers\base_scraper.py", line 39, in run
    self.driver.get(self.link)
  File "C:\Users\Movie Computer\AppData\Local\Programs\Python\Python38\lib\site-packages\selenium\webdriver\remote\webdriver.py", line 333, in get
    self.execute(Command.GET, {'url': url})
  File "C:\Users\Movie Computer\AppData\Local\Programs\Python\Python38\lib\site-packages\selenium\webdriver\remote\webdriver.py", line 321, in execute
    self.error_handler.check_response(response)
  File "C:\Users\Movie Computer\AppData\Local\Programs\Python\Python38\lib\site-packages\selenium\webdriver\remote\errorhandler.py", line 242, in check_response
    raise exception_class(message, screen, stacktrace)
selenium.common.exceptions.WebDriverException: Message: chrome not reachable
  (Session info: chrome=83.0.4103.116)

2020-07-02 18:06:51,496 - WARNING - Retry no. 2
2020-07-02 18:07:03,756 - ERROR - Exception occurred
Traceback (most recent call last):
  File "C:\Users\Movie Computer\Desktop\certification-data-scraper\Scrapers\base_scraper.py", line 39, in run
    self.driver.get(self.link)
  File "C:\Users\Movie Computer\AppData\Local\Programs\Python\Python38\lib\site-packages\selenium\webdriver\remote\webdriver.py", line 333, in get
    self.execute(Command.GET, {'url': url})
  File "C:\Users\Movie Computer\AppData\Local\Programs\Python\Python38\lib\site-packages\selenium\webdriver\remote\webdriver.py", line 321, in execute
    self.error_handler.check_response(response)
  File "C:\Users\Movie Computer\AppData\Local\Programs\Python\Python38\lib\site-packages\selenium\webdriver\remote\errorhandler.py", line 242, in check_response
    raise exception_class(message, screen, stacktrace)
selenium.common.exceptions.WebDriverException: Message: chrome not reachable
  (Session info: chrome=83.0.4103.116)

2020-07-02 18:07:03,756 - WARNING - Retry no. 3
2020-07-02 18:07:16,068 - ERROR - Exception occurred
Traceback (most recent call last):
  File "C:\Users\Movie Computer\Desktop\certification-data-scraper\Scrapers\base_scraper.py", line 39, in run
    self.driver.get(self.link)
  File "C:\Users\Movie Computer\AppData\Local\Programs\Python\Python38\lib\site-packages\selenium\webdriver\remote\webdriver.py", line 333, in get
    self.execute(Command.GET, {'url': url})
  File "C:\Users\Movie Computer\AppData\Local\Programs\Python\Python38\lib\site-packages\selenium\webdriver\remote\webdriver.py", line 321, in execute
    self.error_handler.check_response(response)
  File "C:\Users\Movie Computer\AppData\Local\Programs\Python\Python38\lib\site-packages\selenium\webdriver\remote\errorhandler.py", line 242, in check_response
    raise exception_class(message, screen, stacktrace)
selenium.common.exceptions.WebDriverException: Message: chrome not reachable
  (Session info: chrome=83.0.4103.116)

2020-07-02 18:07:16,068 - WARNING - Retry no. 4
2020-07-02 18:07:28,380 - ERROR - Exception occurred
Traceback (most recent call last):
  File "C:\Users\Movie Computer\Desktop\certification-data-scraper\Scrapers\base_scraper.py", line 39, in run
    self.driver.get(self.link)
  File "C:\Users\Movie Computer\AppData\Local\Programs\Python\Python38\lib\site-packages\selenium\webdriver\remote\webdriver.py", line 333, in get
    self.execute(Command.GET, {'url': url})
  File "C:\Users\Movie Computer\AppData\Local\Programs\Python\Python38\lib\site-packages\selenium\webdriver\remote\webdriver.py", line 321, in execute
    self.error_handler.check_response(response)
  File "C:\Users\Movie Computer\AppData\Local\Programs\Python\Python38\lib\site-packages\selenium\webdriver\remote\errorhandler.py", line 242, in check_response
    raise exception_class(message, screen, stacktrace)
selenium.common.exceptions.WebDriverException: Message: chrome not reachable
  (Session info: chrome=83.0.4103.116)

2020-07-02 18:07:28,380 - WARNING - Retry no. 5
2020-07-02 18:07:28,380 - WARNING - Maximum retries exceeded, quitting program and saving logs.
2020-07-02 18:10:33,525 - WARNING - file_cache is unavailable when using oauth2client >= 4.0.0 or google-auth
Traceback (most recent call last):
  File "C:\Users\Movie Computer\AppData\Local\Programs\Python\Python38\lib\site-packages\googleapiclient\discovery_cache\__init__.py", line 36, in autodetect
    from google.appengine.api import memcache
ModuleNotFoundError: No module named 'google.appengine'

During handling of the above exception, another exception occurred:

Traceback (most recent call last):
  File "C:\Users\Movie Computer\AppData\Local\Programs\Python\Python38\lib\site-packages\googleapiclient\discovery_cache\file_cache.py", line 33, in <module>
    from oauth2client.contrib.locked_file import LockedFile
ModuleNotFoundError: No module named 'oauth2client.contrib.locked_file'

During handling of the above exception, another exception occurred:

Traceback (most recent call last):
  File "C:\Users\Movie Computer\AppData\Local\Programs\Python\Python38\lib\site-packages\googleapiclient\discovery_cache\file_cache.py", line 37, in <module>
    from oauth2client.locked_file import LockedFile
ModuleNotFoundError: No module named 'oauth2client.locked_file'

During handling of the above exception, another exception occurred:

Traceback (most recent call last):
  File "C:\Users\Movie Computer\AppData\Local\Programs\Python\Python38\lib\site-packages\googleapiclient\discovery_cache\__init__.py", line 42, in autodetect
    from . import file_cache
  File "C:\Users\Movie Computer\AppData\Local\Programs\Python\Python38\lib\site-packages\googleapiclient\discovery_cache\file_cache.py", line 40, in <module>
    raise ImportError(
ImportError: file_cache is unavailable when using oauth2client >= 4.0.0 or google-auth
2020-07-02 18:14:13,007 - WARNING - file_cache is unavailable when using oauth2client >= 4.0.0 or google-auth
Traceback (most recent call last):
  File "C:\Users\Movie Computer\AppData\Local\Programs\Python\Python38\lib\site-packages\googleapiclient\discovery_cache\__init__.py", line 36, in autodetect
    from google.appengine.api import memcache
ModuleNotFoundError: No module named 'google.appengine'

During handling of the above exception, another exception occurred:

Traceback (most recent call last):
  File "C:\Users\Movie Computer\AppData\Local\Programs\Python\Python38\lib\site-packages\googleapiclient\discovery_cache\file_cache.py", line 33, in <module>
    from oauth2client.contrib.locked_file import LockedFile
ModuleNotFoundError: No module named 'oauth2client.contrib.locked_file'

During handling of the above exception, another exception occurred:

Traceback (most recent call last):
  File "C:\Users\Movie Computer\AppData\Local\Programs\Python\Python38\lib\site-packages\googleapiclient\discovery_cache\file_cache.py", line 37, in <module>
    from oauth2client.locked_file import LockedFile
ModuleNotFoundError: No module named 'oauth2client.locked_file'

During handling of the above exception, another exception occurred:

Traceback (most recent call last):
  File "C:\Users\Movie Computer\AppData\Local\Programs\Python\Python38\lib\site-packages\googleapiclient\discovery_cache\__init__.py", line 42, in autodetect
    from . import file_cache
  File "C:\Users\Movie Computer\AppData\Local\Programs\Python\Python38\lib\site-packages\googleapiclient\discovery_cache\file_cache.py", line 40, in <module>
    raise ImportError(
ImportError: file_cache is unavailable when using oauth2client >= 4.0.0 or google-auth
2020-07-02 18:18:58,204 - WARNING - file_cache is unavailable when using oauth2client >= 4.0.0 or google-auth
Traceback (most recent call last):
  File "C:\Users\Movie Computer\AppData\Local\Programs\Python\Python38\lib\site-packages\googleapiclient\discovery_cache\__init__.py", line 36, in autodetect
    from google.appengine.api import memcache
ModuleNotFoundError: No module named 'google.appengine'

During handling of the above exception, another exception occurred:

Traceback (most recent call last):
  File "C:\Users\Movie Computer\AppData\Local\Programs\Python\Python38\lib\site-packages\googleapiclient\discovery_cache\file_cache.py", line 33, in <module>
    from oauth2client.contrib.locked_file import LockedFile
ModuleNotFoundError: No module named 'oauth2client.contrib.locked_file'

During handling of the above exception, another exception occurred:

Traceback (most recent call last):
  File "C:\Users\Movie Computer\AppData\Local\Programs\Python\Python38\lib\site-packages\googleapiclient\discovery_cache\file_cache.py", line 37, in <module>
    from oauth2client.locked_file import LockedFile
ModuleNotFoundError: No module named 'oauth2client.locked_file'

During handling of the above exception, another exception occurred:

Traceback (most recent call last):
  File "C:\Users\Movie Computer\AppData\Local\Programs\Python\Python38\lib\site-packages\googleapiclient\discovery_cache\__init__.py", line 42, in autodetect
    from . import file_cache
  File "C:\Users\Movie Computer\AppData\Local\Programs\Python\Python38\lib\site-packages\googleapiclient\discovery_cache\file_cache.py", line 40, in <module>
    raise ImportError(
ImportError: file_cache is unavailable when using oauth2client >= 4.0.0 or google-auth
2020-07-02 18:22:38,567 - WARNING - file_cache is unavailable when using oauth2client >= 4.0.0 or google-auth
Traceback (most recent call last):
  File "C:\Users\Movie Computer\AppData\Local\Programs\Python\Python38\lib\site-packages\googleapiclient\discovery_cache\__init__.py", line 36, in autodetect
    from google.appengine.api import memcache
ModuleNotFoundError: No module named 'google.appengine'

During handling of the above exception, another exception occurred:

Traceback (most recent call last):
  File "C:\Users\Movie Computer\AppData\Local\Programs\Python\Python38\lib\site-packages\googleapiclient\discovery_cache\file_cache.py", line 33, in <module>
    from oauth2client.contrib.locked_file import LockedFile
ModuleNotFoundError: No module named 'oauth2client.contrib.locked_file'

During handling of the above exception, another exception occurred:

Traceback (most recent call last):
  File "C:\Users\Movie Computer\AppData\Local\Programs\Python\Python38\lib\site-packages\googleapiclient\discovery_cache\file_cache.py", line 37, in <module>
    from oauth2client.locked_file import LockedFile
ModuleNotFoundError: No module named 'oauth2client.locked_file'

During handling of the above exception, another exception occurred:

Traceback (most recent call last):
  File "C:\Users\Movie Computer\AppData\Local\Programs\Python\Python38\lib\site-packages\googleapiclient\discovery_cache\__init__.py", line 42, in autodetect
    from . import file_cache
  File "C:\Users\Movie Computer\AppData\Local\Programs\Python\Python38\lib\site-packages\googleapiclient\discovery_cache\file_cache.py", line 40, in <module>
    raise ImportError(
ImportError: file_cache is unavailable when using oauth2client >= 4.0.0 or google-auth
2020-07-02 18:31:10,023 - WARNING - file_cache is unavailable when using oauth2client >= 4.0.0 or google-auth
Traceback (most recent call last):
  File "C:\Users\Movie Computer\AppData\Local\Programs\Python\Python38\lib\site-packages\googleapiclient\discovery_cache\__init__.py", line 36, in autodetect
    from google.appengine.api import memcache
ModuleNotFoundError: No module named 'google.appengine'

During handling of the above exception, another exception occurred:

Traceback (most recent call last):
  File "C:\Users\Movie Computer\AppData\Local\Programs\Python\Python38\lib\site-packages\googleapiclient\discovery_cache\file_cache.py", line 33, in <module>
    from oauth2client.contrib.locked_file import LockedFile
ModuleNotFoundError: No module named 'oauth2client.contrib.locked_file'

During handling of the above exception, another exception occurred:

Traceback (most recent call last):
  File "C:\Users\Movie Computer\AppData\Local\Programs\Python\Python38\lib\site-packages\googleapiclient\discovery_cache\file_cache.py", line 37, in <module>
    from oauth2client.locked_file import LockedFile
ModuleNotFoundError: No module named 'oauth2client.locked_file'

During handling of the above exception, another exception occurred:

Traceback (most recent call last):
  File "C:\Users\Movie Computer\AppData\Local\Programs\Python\Python38\lib\site-packages\googleapiclient\discovery_cache\__init__.py", line 42, in autodetect
    from . import file_cache
  File "C:\Users\Movie Computer\AppData\Local\Programs\Python\Python38\lib\site-packages\googleapiclient\discovery_cache\file_cache.py", line 40, in <module>
    raise ImportError(
ImportError: file_cache is unavailable when using oauth2client >= 4.0.0 or google-auth
2020-07-02 18:34:45,634 - WARNING - file_cache is unavailable when using oauth2client >= 4.0.0 or google-auth
Traceback (most recent call last):
  File "C:\Users\Movie Computer\AppData\Local\Programs\Python\Python38\lib\site-packages\googleapiclient\discovery_cache\__init__.py", line 36, in autodetect
    from google.appengine.api import memcache
ModuleNotFoundError: No module named 'google.appengine'

During handling of the above exception, another exception occurred:

Traceback (most recent call last):
  File "C:\Users\Movie Computer\AppData\Local\Programs\Python\Python38\lib\site-packages\googleapiclient\discovery_cache\file_cache.py", line 33, in <module>
    from oauth2client.contrib.locked_file import LockedFile
ModuleNotFoundError: No module named 'oauth2client.contrib.locked_file'

During handling of the above exception, another exception occurred:

Traceback (most recent call last):
  File "C:\Users\Movie Computer\AppData\Local\Programs\Python\Python38\lib\site-packages\googleapiclient\discovery_cache\file_cache.py", line 37, in <module>
    from oauth2client.locked_file import LockedFile
ModuleNotFoundError: No module named 'oauth2client.locked_file'

During handling of the above exception, another exception occurred:

Traceback (most recent call last):
  File "C:\Users\Movie Computer\AppData\Local\Programs\Python\Python38\lib\site-packages\googleapiclient\discovery_cache\__init__.py", line 42, in autodetect
    from . import file_cache
  File "C:\Users\Movie Computer\AppData\Local\Programs\Python\Python38\lib\site-packages\googleapiclient\discovery_cache\file_cache.py", line 40, in <module>
    raise ImportError(
ImportError: file_cache is unavailable when using oauth2client >= 4.0.0 or google-auth
2020-07-02 18:40:47,042 - ERROR - Exception occurred
Traceback (most recent call last):
  File "C:\Users\Movie Computer\Desktop\certification-data-scraper\Scrapers\base_scraper.py", line 55, in run
    self.data_list.append(self.click_links())
  File "C:\Users\Movie Computer\Desktop\certification-data-scraper\Scrapers\Asia\eprocure.py", line 33, in click_links
    data = self.get_data()
  File "C:\Users\Movie Computer\Desktop\certification-data-scraper\Scrapers\Asia\eprocure.py", line 47, in get_data
    info_list.append(soup.find('td', string="ePublished Date").find_next_siblings(width="20%")[0].text.strip())
AttributeError: 'NoneType' object has no attribute 'find_next_siblings'
2020-07-02 18:40:47,061 - WARNING - Retry no. 1
2020-07-02 18:42:33,460 - WARNING - file_cache is unavailable when using oauth2client >= 4.0.0 or google-auth
Traceback (most recent call last):
  File "C:\Users\Movie Computer\AppData\Local\Programs\Python\Python38\lib\site-packages\googleapiclient\discovery_cache\__init__.py", line 36, in autodetect
    from google.appengine.api import memcache
ModuleNotFoundError: No module named 'google.appengine'

During handling of the above exception, another exception occurred:

Traceback (most recent call last):
  File "C:\Users\Movie Computer\AppData\Local\Programs\Python\Python38\lib\site-packages\googleapiclient\discovery_cache\file_cache.py", line 33, in <module>
    from oauth2client.contrib.locked_file import LockedFile
ModuleNotFoundError: No module named 'oauth2client.contrib.locked_file'

During handling of the above exception, another exception occurred:

Traceback (most recent call last):
  File "C:\Users\Movie Computer\AppData\Local\Programs\Python\Python38\lib\site-packages\googleapiclient\discovery_cache\file_cache.py", line 37, in <module>
    from oauth2client.locked_file import LockedFile
ModuleNotFoundError: No module named 'oauth2client.locked_file'

During handling of the above exception, another exception occurred:

Traceback (most recent call last):
  File "C:\Users\Movie Computer\AppData\Local\Programs\Python\Python38\lib\site-packages\googleapiclient\discovery_cache\__init__.py", line 42, in autodetect
    from . import file_cache
  File "C:\Users\Movie Computer\AppData\Local\Programs\Python\Python38\lib\site-packages\googleapiclient\discovery_cache\file_cache.py", line 40, in <module>
    raise ImportError(
ImportError: file_cache is unavailable when using oauth2client >= 4.0.0 or google-auth
2020-07-02 18:46:58,245 - WARNING - file_cache is unavailable when using oauth2client >= 4.0.0 or google-auth
Traceback (most recent call last):
  File "C:\Users\Movie Computer\AppData\Local\Programs\Python\Python38\lib\site-packages\googleapiclient\discovery_cache\__init__.py", line 36, in autodetect
    from google.appengine.api import memcache
ModuleNotFoundError: No module named 'google.appengine'

During handling of the above exception, another exception occurred:

Traceback (most recent call last):
  File "C:\Users\Movie Computer\AppData\Local\Programs\Python\Python38\lib\site-packages\googleapiclient\discovery_cache\file_cache.py", line 33, in <module>
    from oauth2client.contrib.locked_file import LockedFile
ModuleNotFoundError: No module named 'oauth2client.contrib.locked_file'

During handling of the above exception, another exception occurred:

Traceback (most recent call last):
  File "C:\Users\Movie Computer\AppData\Local\Programs\Python\Python38\lib\site-packages\googleapiclient\discovery_cache\file_cache.py", line 37, in <module>
    from oauth2client.locked_file import LockedFile
ModuleNotFoundError: No module named 'oauth2client.locked_file'

During handling of the above exception, another exception occurred:

Traceback (most recent call last):
  File "C:\Users\Movie Computer\AppData\Local\Programs\Python\Python38\lib\site-packages\googleapiclient\discovery_cache\__init__.py", line 42, in autodetect
    from . import file_cache
  File "C:\Users\Movie Computer\AppData\Local\Programs\Python\Python38\lib\site-packages\googleapiclient\discovery_cache\file_cache.py", line 40, in <module>
    raise ImportError(
ImportError: file_cache is unavailable when using oauth2client >= 4.0.0 or google-auth
2020-07-02 18:47:40,347 - WARNING - file_cache is unavailable when using oauth2client >= 4.0.0 or google-auth
Traceback (most recent call last):
  File "C:\Users\Movie Computer\AppData\Local\Programs\Python\Python38\lib\site-packages\googleapiclient\discovery_cache\__init__.py", line 36, in autodetect
    from google.appengine.api import memcache
ModuleNotFoundError: No module named 'google.appengine'

During handling of the above exception, another exception occurred:

Traceback (most recent call last):
  File "C:\Users\Movie Computer\AppData\Local\Programs\Python\Python38\lib\site-packages\googleapiclient\discovery_cache\file_cache.py", line 33, in <module>
    from oauth2client.contrib.locked_file import LockedFile
ModuleNotFoundError: No module named 'oauth2client.contrib.locked_file'

During handling of the above exception, another exception occurred:

Traceback (most recent call last):
  File "C:\Users\Movie Computer\AppData\Local\Programs\Python\Python38\lib\site-packages\googleapiclient\discovery_cache\file_cache.py", line 37, in <module>
    from oauth2client.locked_file import LockedFile
ModuleNotFoundError: No module named 'oauth2client.locked_file'

During handling of the above exception, another exception occurred:

Traceback (most recent call last):
  File "C:\Users\Movie Computer\AppData\Local\Programs\Python\Python38\lib\site-packages\googleapiclient\discovery_cache\__init__.py", line 42, in autodetect
    from . import file_cache
  File "C:\Users\Movie Computer\AppData\Local\Programs\Python\Python38\lib\site-packages\googleapiclient\discovery_cache\file_cache.py", line 40, in <module>
    raise ImportError(
ImportError: file_cache is unavailable when using oauth2client >= 4.0.0 or google-auth
2020-07-02 18:47:43,511 - WARNING - file_cache is unavailable when using oauth2client >= 4.0.0 or google-auth
Traceback (most recent call last):
  File "C:\Users\Movie Computer\AppData\Local\Programs\Python\Python38\lib\site-packages\googleapiclient\discovery_cache\__init__.py", line 36, in autodetect
    from google.appengine.api import memcache
ModuleNotFoundError: No module named 'google.appengine'

During handling of the above exception, another exception occurred:

Traceback (most recent call last):
  File "C:\Users\Movie Computer\AppData\Local\Programs\Python\Python38\lib\site-packages\googleapiclient\discovery_cache\file_cache.py", line 33, in <module>
    from oauth2client.contrib.locked_file import LockedFile
ModuleNotFoundError: No module named 'oauth2client.contrib.locked_file'

During handling of the above exception, another exception occurred:

Traceback (most recent call last):
  File "C:\Users\Movie Computer\AppData\Local\Programs\Python\Python38\lib\site-packages\googleapiclient\discovery_cache\file_cache.py", line 37, in <module>
    from oauth2client.locked_file import LockedFile
ModuleNotFoundError: No module named 'oauth2client.locked_file'

During handling of the above exception, another exception occurred:

Traceback (most recent call last):
  File "C:\Users\Movie Computer\AppData\Local\Programs\Python\Python38\lib\site-packages\googleapiclient\discovery_cache\__init__.py", line 42, in autodetect
    from . import file_cache
  File "C:\Users\Movie Computer\AppData\Local\Programs\Python\Python38\lib\site-packages\googleapiclient\discovery_cache\file_cache.py", line 40, in <module>
    raise ImportError(
ImportError: file_cache is unavailable when using oauth2client >= 4.0.0 or google-auth
2020-07-02 18:47:47,097 - WARNING - file_cache is unavailable when using oauth2client >= 4.0.0 or google-auth
Traceback (most recent call last):
  File "C:\Users\Movie Computer\AppData\Local\Programs\Python\Python38\lib\site-packages\googleapiclient\discovery_cache\__init__.py", line 36, in autodetect
    from google.appengine.api import memcache
ModuleNotFoundError: No module named 'google.appengine'

During handling of the above exception, another exception occurred:

Traceback (most recent call last):
  File "C:\Users\Movie Computer\AppData\Local\Programs\Python\Python38\lib\site-packages\googleapiclient\discovery_cache\file_cache.py", line 33, in <module>
    from oauth2client.contrib.locked_file import LockedFile
ModuleNotFoundError: No module named 'oauth2client.contrib.locked_file'

During handling of the above exception, another exception occurred:

Traceback (most recent call last):
  File "C:\Users\Movie Computer\AppData\Local\Programs\Python\Python38\lib\site-packages\googleapiclient\discovery_cache\file_cache.py", line 37, in <module>
    from oauth2client.locked_file import LockedFile
ModuleNotFoundError: No module named 'oauth2client.locked_file'

During handling of the above exception, another exception occurred:

Traceback (most recent call last):
  File "C:\Users\Movie Computer\AppData\Local\Programs\Python\Python38\lib\site-packages\googleapiclient\discovery_cache\__init__.py", line 42, in autodetect
    from . import file_cache
  File "C:\Users\Movie Computer\AppData\Local\Programs\Python\Python38\lib\site-packages\googleapiclient\discovery_cache\file_cache.py", line 40, in <module>
    raise ImportError(
ImportError: file_cache is unavailable when using oauth2client >= 4.0.0 or google-auth
2020-07-02 18:47:51,501 - WARNING - file_cache is unavailable when using oauth2client >= 4.0.0 or google-auth
Traceback (most recent call last):
  File "C:\Users\Movie Computer\AppData\Local\Programs\Python\Python38\lib\site-packages\googleapiclient\discovery_cache\__init__.py", line 36, in autodetect
    from google.appengine.api import memcache
ModuleNotFoundError: No module named 'google.appengine'

During handling of the above exception, another exception occurred:

Traceback (most recent call last):
  File "C:\Users\Movie Computer\AppData\Local\Programs\Python\Python38\lib\site-packages\googleapiclient\discovery_cache\file_cache.py", line 33, in <module>
    from oauth2client.contrib.locked_file import LockedFile
ModuleNotFoundError: No module named 'oauth2client.contrib.locked_file'

During handling of the above exception, another exception occurred:

Traceback (most recent call last):
  File "C:\Users\Movie Computer\AppData\Local\Programs\Python\Python38\lib\site-packages\googleapiclient\discovery_cache\file_cache.py", line 37, in <module>
    from oauth2client.locked_file import LockedFile
ModuleNotFoundError: No module named 'oauth2client.locked_file'

During handling of the above exception, another exception occurred:

Traceback (most recent call last):
  File "C:\Users\Movie Computer\AppData\Local\Programs\Python\Python38\lib\site-packages\googleapiclient\discovery_cache\__init__.py", line 42, in autodetect
    from . import file_cache
  File "C:\Users\Movie Computer\AppData\Local\Programs\Python\Python38\lib\site-packages\googleapiclient\discovery_cache\file_cache.py", line 40, in <module>
    raise ImportError(
ImportError: file_cache is unavailable when using oauth2client >= 4.0.0 or google-auth
2020-07-02 18:59:03,825 - ERROR - Exception occurred
Traceback (most recent call last):
  File "C:\Users\Movie Computer\Desktop\certification-data-scraper\Scrapers\base_scraper.py", line 55, in run
    self.data_list.append(self.click_links())
  File "C:\Users\Movie Computer\Desktop\certification-data-scraper\Scrapers\Asia\eprocure.py", line 33, in click_links
    data = self.get_data()
  File "C:\Users\Movie Computer\Desktop\certification-data-scraper\Scrapers\Asia\eprocure.py", line 47, in get_data
    info_list.append(soup.find('td', string="ePublished Date").find_next_siblings(width="20%")[0].text.strip())
AttributeError: 'NoneType' object has no attribute 'find_next_siblings'
2020-07-02 18:59:03,833 - WARNING - Retry no. 1
2020-07-02 19:00:38,983 - WARNING - file_cache is unavailable when using oauth2client >= 4.0.0 or google-auth
Traceback (most recent call last):
  File "C:\Users\Movie Computer\AppData\Local\Programs\Python\Python38\lib\site-packages\googleapiclient\discovery_cache\__init__.py", line 36, in autodetect
    from google.appengine.api import memcache
ModuleNotFoundError: No module named 'google.appengine'

During handling of the above exception, another exception occurred:

Traceback (most recent call last):
  File "C:\Users\Movie Computer\AppData\Local\Programs\Python\Python38\lib\site-packages\googleapiclient\discovery_cache\file_cache.py", line 33, in <module>
    from oauth2client.contrib.locked_file import LockedFile
ModuleNotFoundError: No module named 'oauth2client.contrib.locked_file'

During handling of the above exception, another exception occurred:

Traceback (most recent call last):
  File "C:\Users\Movie Computer\AppData\Local\Programs\Python\Python38\lib\site-packages\googleapiclient\discovery_cache\file_cache.py", line 37, in <module>
    from oauth2client.locked_file import LockedFile
ModuleNotFoundError: No module named 'oauth2client.locked_file'

During handling of the above exception, another exception occurred:

Traceback (most recent call last):
  File "C:\Users\Movie Computer\AppData\Local\Programs\Python\Python38\lib\site-packages\googleapiclient\discovery_cache\__init__.py", line 42, in autodetect
    from . import file_cache
  File "C:\Users\Movie Computer\AppData\Local\Programs\Python\Python38\lib\site-packages\googleapiclient\discovery_cache\file_cache.py", line 40, in <module>
    raise ImportError(
ImportError: file_cache is unavailable when using oauth2client >= 4.0.0 or google-auth
2020-07-02 19:01:17,539 - WARNING - file_cache is unavailable when using oauth2client >= 4.0.0 or google-auth
Traceback (most recent call last):
  File "C:\Users\Movie Computer\AppData\Local\Programs\Python\Python38\lib\site-packages\googleapiclient\discovery_cache\__init__.py", line 36, in autodetect
    from google.appengine.api import memcache
ModuleNotFoundError: No module named 'google.appengine'

During handling of the above exception, another exception occurred:

Traceback (most recent call last):
  File "C:\Users\Movie Computer\AppData\Local\Programs\Python\Python38\lib\site-packages\googleapiclient\discovery_cache\file_cache.py", line 33, in <module>
    from oauth2client.contrib.locked_file import LockedFile
ModuleNotFoundError: No module named 'oauth2client.contrib.locked_file'

During handling of the above exception, another exception occurred:

Traceback (most recent call last):
  File "C:\Users\Movie Computer\AppData\Local\Programs\Python\Python38\lib\site-packages\googleapiclient\discovery_cache\file_cache.py", line 37, in <module>
    from oauth2client.locked_file import LockedFile
ModuleNotFoundError: No module named 'oauth2client.locked_file'

During handling of the above exception, another exception occurred:

Traceback (most recent call last):
  File "C:\Users\Movie Computer\AppData\Local\Programs\Python\Python38\lib\site-packages\googleapiclient\discovery_cache\__init__.py", line 42, in autodetect
    from . import file_cache
  File "C:\Users\Movie Computer\AppData\Local\Programs\Python\Python38\lib\site-packages\googleapiclient\discovery_cache\file_cache.py", line 40, in <module>
    raise ImportError(
ImportError: file_cache is unavailable when using oauth2client >= 4.0.0 or google-auth
2020-07-02 19:01:21,809 - WARNING - file_cache is unavailable when using oauth2client >= 4.0.0 or google-auth
Traceback (most recent call last):
  File "C:\Users\Movie Computer\AppData\Local\Programs\Python\Python38\lib\site-packages\googleapiclient\discovery_cache\__init__.py", line 36, in autodetect
    from google.appengine.api import memcache
ModuleNotFoundError: No module named 'google.appengine'

During handling of the above exception, another exception occurred:

Traceback (most recent call last):
  File "C:\Users\Movie Computer\AppData\Local\Programs\Python\Python38\lib\site-packages\googleapiclient\discovery_cache\file_cache.py", line 33, in <module>
    from oauth2client.contrib.locked_file import LockedFile
ModuleNotFoundError: No module named 'oauth2client.contrib.locked_file'

During handling of the above exception, another exception occurred:

Traceback (most recent call last):
  File "C:\Users\Movie Computer\AppData\Local\Programs\Python\Python38\lib\site-packages\googleapiclient\discovery_cache\file_cache.py", line 37, in <module>
    from oauth2client.locked_file import LockedFile
ModuleNotFoundError: No module named 'oauth2client.locked_file'

During handling of the above exception, another exception occurred:

Traceback (most recent call last):
  File "C:\Users\Movie Computer\AppData\Local\Programs\Python\Python38\lib\site-packages\googleapiclient\discovery_cache\__init__.py", line 42, in autodetect
    from . import file_cache
  File "C:\Users\Movie Computer\AppData\Local\Programs\Python\Python38\lib\site-packages\googleapiclient\discovery_cache\file_cache.py", line 40, in <module>
    raise ImportError(
ImportError: file_cache is unavailable when using oauth2client >= 4.0.0 or google-auth
2020-07-02 19:01:27,045 - WARNING - file_cache is unavailable when using oauth2client >= 4.0.0 or google-auth
Traceback (most recent call last):
  File "C:\Users\Movie Computer\AppData\Local\Programs\Python\Python38\lib\site-packages\googleapiclient\discovery_cache\__init__.py", line 36, in autodetect
    from google.appengine.api import memcache
ModuleNotFoundError: No module named 'google.appengine'

During handling of the above exception, another exception occurred:

Traceback (most recent call last):
  File "C:\Users\Movie Computer\AppData\Local\Programs\Python\Python38\lib\site-packages\googleapiclient\discovery_cache\file_cache.py", line 33, in <module>
    from oauth2client.contrib.locked_file import LockedFile
ModuleNotFoundError: No module named 'oauth2client.contrib.locked_file'

During handling of the above exception, another exception occurred:

Traceback (most recent call last):
  File "C:\Users\Movie Computer\AppData\Local\Programs\Python\Python38\lib\site-packages\googleapiclient\discovery_cache\file_cache.py", line 37, in <module>
    from oauth2client.locked_file import LockedFile
ModuleNotFoundError: No module named 'oauth2client.locked_file'

During handling of the above exception, another exception occurred:

Traceback (most recent call last):
  File "C:\Users\Movie Computer\AppData\Local\Programs\Python\Python38\lib\site-packages\googleapiclient\discovery_cache\__init__.py", line 42, in autodetect
    from . import file_cache
  File "C:\Users\Movie Computer\AppData\Local\Programs\Python\Python38\lib\site-packages\googleapiclient\discovery_cache\file_cache.py", line 40, in <module>
    raise ImportError(
ImportError: file_cache is unavailable when using oauth2client >= 4.0.0 or google-auth
2020-07-02 19:01:31,447 - WARNING - file_cache is unavailable when using oauth2client >= 4.0.0 or google-auth
Traceback (most recent call last):
  File "C:\Users\Movie Computer\AppData\Local\Programs\Python\Python38\lib\site-packages\googleapiclient\discovery_cache\__init__.py", line 36, in autodetect
    from google.appengine.api import memcache
ModuleNotFoundError: No module named 'google.appengine'

During handling of the above exception, another exception occurred:

Traceback (most recent call last):
  File "C:\Users\Movie Computer\AppData\Local\Programs\Python\Python38\lib\site-packages\googleapiclient\discovery_cache\file_cache.py", line 33, in <module>
    from oauth2client.contrib.locked_file import LockedFile
ModuleNotFoundError: No module named 'oauth2client.contrib.locked_file'

During handling of the above exception, another exception occurred:

Traceback (most recent call last):
  File "C:\Users\Movie Computer\AppData\Local\Programs\Python\Python38\lib\site-packages\googleapiclient\discovery_cache\file_cache.py", line 37, in <module>
    from oauth2client.locked_file import LockedFile
ModuleNotFoundError: No module named 'oauth2client.locked_file'

During handling of the above exception, another exception occurred:

Traceback (most recent call last):
  File "C:\Users\Movie Computer\AppData\Local\Programs\Python\Python38\lib\site-packages\googleapiclient\discovery_cache\__init__.py", line 42, in autodetect
    from . import file_cache
  File "C:\Users\Movie Computer\AppData\Local\Programs\Python\Python38\lib\site-packages\googleapiclient\discovery_cache\file_cache.py", line 40, in <module>
    raise ImportError(
ImportError: file_cache is unavailable when using oauth2client >= 4.0.0 or google-auth
